Workbook

Sheet 使用說明
A1: 類別 | B1: 說明
A2: 資料狀態 | B2: ★ 本檔所有球員姓名、成績數據、球隊戰績均為程式模擬產生，非 2024-2026 年真實比賽結果。
A3: 資料狀態 | B3: ★ 球員姓名為虛構，如與真實人物雷同純屬巧合；請勿將本檔數據當作實際參考資料引用。
A4: 資料狀態 | B4: 球隊代號、英文隊名、聯盟與分區歸屬為真實架構，可直接沿用；其餘欄位請以官方資料覆蓋。
A5: 資料來源建議 | B5: 真實資料可取自 MLB Stats API (statsapi.mlb.com)、Baseball Savant、FanGraphs 或 Baseball Reference。
A6: 資料來源建議 | B6: 本檔欄位代碼對齊 MLB Stats API 命名（homeRuns、plateAppearances、inningsPitched 等），可直接對應匯入。
A7: 結構規範 | B7: 每張資料工作表第 1 列為欄位標題，第 2 列起為資料，無空列、無小計或合計列。
A8: 結構規範 | B8: 全檔無合併儲存格、無標題橫幅，可直接以 pandas.read_excel(header=0) 讀取。
A9: 結構規範 | B9: 每張資料工作表皆已定義為 Excel 表格物件，名稱為 tbl_ 開頭，可供 BI 工具直接指定資料來源。
A10: 結構規範 | B10: 事實表皆依 球季 → 球隊 → 球員 排序，同一球季的資料為連續區塊，方便切片。
A11: 多季設計 | B11: ★ 所屬球隊放在事實表而非球員主檔，因為球員會轉隊；同一球員不同球季可能有不同球隊代號。
A12: 多季設計 | B12: ★ 球員主檔的「最新所屬球隊」僅代表最後一個有出賽紀錄的球季，不可用來回推歷史球季的隸屬。
... A35: 圖表 | B35: 「圖表預覽」工作表僅供人工檢視，不含任何原始資料，自動化流程可略過該表。

Sheet 欄位定義
A1: 工作表 | B1: 欄位位置 | C1: 欄位代碼 | D1: 中文欄名 | E1: 資料型別 | F1: 單位 | G1: 資料來源
A2: 球季參數 | B2: A | C2: season | D2: 球季 | E2: 整數 | F2: 年 | G2: 手動輸入
A3: 球季參數 | B3: B | C3: games_total | D3: 例行賽場次 | E3: 整數 | F3: 場 | G3: 手動輸入
A4: 球季參數 | B4: C | C4: fip_constant | D4: FIP 常數 | E4: 數值 | G4: 手動輸入
A5: 球季參數 | B5: D | C5: pythag_exp | D5: 畢氏勝率指數 | E5: 數值 | G5: 手動輸入
A6: 球季參數 | B6: E | C6: qual_pa | D6: 打者合格打席門檻 | E6: 整數 | F6: 打席 | G6: 手動輸入
A7: 球季參數 | B7: F | C7: qual_ip | D7: 投手合格局數門檻 | E7: 整數 | F7: 局 | G7: 手動輸入
A8: 球隊主檔 | B8: A | C8: team_id | D8: 球隊代號 | E8: 文字 | G8: 手動輸入
A9: 球隊主檔 | B9: B | C9: team_name_en | D9: 球隊英文名 | E9: 文字 | G9: 手動輸入
A10: 球隊主檔 | B10: C | C10: team_name_zh | D10: 球隊中文名 | E10: 文字 | G10: 手動輸入
A11: 球隊主檔 | B11: D | C11: league | D11: 聯盟 | E11: 文字 | G11: 手動輸入
A12: 球隊主檔 | B12: E | C12: division | D12: 分區 | E12: 文字 | G12: 手動輸入
A13: 球隊主檔 | B13: F | C13: location | D13: 所在地 | E13: 文字 | G13: 手動輸入
A14: 球員主檔 | B14: A | C14: player_id | D14: 球員代號 | E14: 文字 | G14: 手動輸入
A15: 球員主檔 | B15: B | C15: player_name | D15: 球員姓名 | E15: 文字 | G15: 手動輸入
A16: 球員主檔 | B16: C | C16: player_type | D16: 球員類別 | E16: 文字 | F16: 打者/投手 | G16: 手動輸入
A17: 球員主檔 | B17: D | C17: primary_position | D17: 主要守備位置 | E17: 文字 | G17: 手動輸入
A18: 球員主檔 | B18: E | C18: bat_side | D18: 打擊慣用手 | E18: 文字 | F18: R/L/S | G18: 手動輸入
A19: 球員主檔 | B19: F | C19: pitch_hand | D19: 投球慣用手 | E19: 文字 | F19: R/L | G19: 手動輸入
A20: 球員主檔 | B20: G | C20: birth_date | D20: 出生日期 | E20: 日期 | G20: 手動輸入
A21: 球員主檔 | B21: H | C21: height_cm | D21: 身高 | E21: 整數 | F21: 公分 | G21: 手動輸入
A22: 球員主檔 | B22: I | C22: weight_kg | D22: 體重 | E22: 整數 | F22: 公斤 | G22: 手動輸入
A23: 球員主檔 | B23: J | C23: debut_year | D23: 大聯盟初登板年 | E23: 整數 | F23: 年 | G23: 手動輸入
A24: 球員主檔 | B24: K | C24: latest_team_id | D24: 最新所屬球隊代號 | E24: 文字 | G24: 手動輸入
A25: 球員主檔 | B25: L | C25: latest_team_name | D25: 最新所屬球隊 | E25: 文字 | G25: 連結 球隊主檔
A26: 球員主檔 | B26: M | C26: seasons_played | D26: 出賽球季數 | E26: 整數 | F26: 季 | G26: 公式
A27: 打擊成績 | B27: A | C27: season | D27: 球季 | E27: 整數 | F27: 年 | G27: 手動輸入
A28: 打擊成績 | B28: B | C28: player_id | D28: 球員代號 | E28: 文字 | G28: 手動輸入
A29: 打擊成績 | B29: C | C29: player_name | D29: 球員姓名 | E29: 文字 | G29: 連結 球員主檔
A30: 打擊成績 | B30: D | C30: team_id | D30: 球隊代號 | E30: 文字 | G30: 手動輸入
A31: 打擊成績 | B31: E | C31: team_name | D31: 球隊中文名 | E31: 文字 | G31: 連結 球隊主檔
A32: 打擊成績 | B32: F | C32: league | D32: 聯盟 | E32: 文字 | G32: 連結 球隊主檔
A33: 打擊成績 | B33: G | C33: position | D33: 該季守備位置 | E33: 文字 | G33: 手動輸入
A34: 打擊成績 | B34: H | C34: age | D34: 球季年齡 | E34: 整數 | F34: 歲 | G34: 公式
A35: 打擊成績 | B35: I | C35: gamesPlayed | D35: 出賽數 | E35: 整數 | F35: G | G35: 手動輸入
A36: 打擊成績 | B36: J | C36: plateAppearances | D36: 打席 | E36: 整數 | F36: PA | G36: 手動輸入
A37: 打擊成績 | B37: K | C37: atBats | D37: 打數 | E37: 整數 | F37: AB | G37: 手動輸入
A38: 打擊成績 | B38: L | C38: runs | D38: 得分 | E38: 整數 | F38: R | G38: 手動輸入
A39: 打擊成績 | B39: M | C39: hits | D39: 安打 | E39: 整數 | F39: H | G39: 手動輸入
A40: 打擊成績 | B40: N | C40: doubles | D40: 二壘打 | E40: 整數 | F40: 2B | G40: 手動輸入
...

Sheet 球季參數
A1: 球季 | B1: 例行賽場次 | C1: FIP 常數 | D1: 畢氏勝率指數 | E1: 打者合格打席門檻 | F1: 投手合格局數門檻
A2: 2024 | B2: 162 | C2: 3.13 | D2: 1.83 | E2: 502 | F2: 162
A3: 2025 | B3: 162 | C3: 3.1 | D3: 1.83 | E3: 502 | F3: 162
A4: 2026 | B4: 162 | C4: 3.08 | D4: 1.83 | E4: 502 | F4: 162

Sheet 球隊主檔
A1: 球隊代號 | B1: 球隊英文名 | C1: 球隊中文名 | D1: 聯盟 | E1: 分區 | F1: 所在地
A2: BAL | B2: Baltimore Orioles | C2: 巴爾的摩金鶯 | D2: 美聯 | E2: 美東 | F2: Baltimore, MD
A3: BOS | B3: Boston Red Sox | C3: 波士頓紅襪 | D3: 美聯 | E3: 美東 | F3: Boston, MA
A4: NYY | B4: New York Yankees | C4: 紐約洋基 | D4: 美聯 | E4: 美東 | F4: Bronx, NY
A5: TBR | B5: Tampa Bay Rays | C5: 坦帕灣光芒 | D5: 美聯 | E5: 美東 | F5: St. Petersburg, FL
A6: TOR | B6: Toronto Blue Jays | C6: 多倫多藍鳥 | D6: 美聯 | E6: 美東 | F6: Toronto, ON
A7: CWS | B7: Chicago White Sox | C7: 芝加哥白襪 | D7: 美聯 | E7: 美中 | F7: Chicago, IL
A8: CLE | B8: Cleveland Guardians | C8: 克里夫蘭守護者 | D8: 美聯 | E8: 美中 | F8: Cleveland, OH
A9: DET | B9: Detroit Tigers | C9: 底特律老虎 | D9: 美聯 | E9: 美中 | F9: Detroit, MI
A10: KCR | B10: Kansas City Royals | C10: 堪薩斯市皇家 | D10: 美聯 | E10: 美中 | F10: Kansas City, MO
A11: MIN | B11: Minnesota Twins | C11: 明尼蘇達雙城 | D11: 美聯 | E11: 美中 | F11: Minneapolis, MN
A12: ATH | B12: Athletics | C12: 運動家 | D12: 美聯 | E12: 美西 | F12: West Sacramento, CA
... A31: SFG | B31: San Francisco Giants | C31: 舊金山巨人 | D31: 國聯 | E31: 國西 | F31: San Francisco, CA

Sheet 球員主檔
A1: 球員代號 | B1: 球員姓名 | C1: 球員類別 | D1: 主要守備位置 | E1: 打擊慣用手 | F1: 投球慣用手 | G1: 出生日期 | H1: 身高 | I1: 體重 | J1: 大聯盟初登板年 | K1: 最新所屬球隊代號 | L1: 最新所屬球隊 | M1: 出賽球季數
A2: P00001 | B2: Leandro Yarbrough | C2: 打者 | D2: CF | E2: R | F2: R | G2: 35447 | H2: 185 | I2: 93 | J2: 2022 | K2: LAA | L2: =INDEX(球隊主檔!$C$2:$C$31,MATCH($K2,球隊主檔!$A$2:$A$31,0)) -> 洛杉磯天使 | M2: =IF($C2="打者",COUNTIF(打擊成績!$B:$B,$A2),COUNTIF(投手成績!$B:$B,$A2)) -> 3
A3: P00002 | B3: Seonwoo Brightwell | C3: 打者 | D3: RF | E3: R | F3: R | G3: 34985 | H3: 186 | I3: 85 | J3: 2015 | K3: BAL | L3: =INDEX(球隊主檔!$C$2:$C$31,MATCH($K3,球隊主檔!$A$2:$A$31,0)) -> 巴爾的摩金鶯 | M3: =IF($C3="打者",COUNTIF(打擊成績!$B:$B,$A3),COUNTIF(投手成績!$B:$B,$A3)) -> 3
A4: P00003 | B4: Jasper Iwasaki | C4: 打者 | D4: 3B | E4: R | F4: R | G4: 36627 | H4: 197 | I4: 90 | J4: 2023 | K4: BAL | L4: =INDEX(球隊主檔!$C$2:$C$31,MATCH($K4,球隊主檔!$A$2:$A$31,0)) -> 巴爾的摩金鶯 | M4: =IF($C4="打者",COUNTIF(打擊成績!$B:$B,$A4),COUNTIF(投手成績!$B:$B,$A4)) -> 3
A5: P00004 | B5: Tristan Lindquist | C5: 打者 | D5: LF | E5: R | F5: L | G5: 36784 | H5: 175 | I5: 80 | J5: 2022 | K5: BAL | L5: =INDEX(球隊主檔!$C$2:$C$31,MATCH($K5,球隊主檔!$A$2:$A$31,0)) -> 巴爾的摩金鶯 | M5: =IF($C5="打者",COUNTIF(打擊成績!$B:$B,$A5),COUNTIF(投手成績!$B:$B,$A5)) -> 3
A6: P00005 | B6: Dashiell Novotný | C6: 打者 | D6: RF | E6: R | F6: R | G6: 33266 | H6: 187 | I6: 79 | J6: 2012 | K6: BAL | L6: =INDEX(球隊主檔!$C$2:$C$31,MATCH($K6,球隊主檔!$A$2:$A$31,0)) -> 巴爾的摩金鶯 | M6: =IF($C6="打者",COUNTIF(打擊成績!$B:$B,$A6),COUNTIF(投手成績!$B:$B,$A6)) -> 1
A7: P00006 | B7: Leandro Esquivel | C7: 打者 | D7: SS | E7: R | F7: L | G7: 35313 | H7: 195 | I7: 92 | J7: 2016 | K7: BAL | L7: =INDEX(球隊主檔!$C$2:$C$31,MATCH($K7,球隊主檔!$A$2:$A$31,0)) -> 巴爾的摩金鶯 | M7: =IF($C7="打者",COUNTIF(打擊成績!$B:$B,$A7),COUNTIF(投手成績!$B:$B,$A7)) -> 3
A8: P00007 | B8: Sawyer Whitmore | C8: 打者 | D8: 1B | E8: L | F8: R | G8: 36897 | H8: 191 | I8: 111 | J8: 2024 | K8: BAL | L8: =INDEX(球隊主檔!$C$2:$C$31,MATCH($K8,球隊主檔!$A$2:$A$31,0)) -> 巴爾的摩金鶯 | M8: =IF($C8="打者",COUNTIF(打擊成績!$B:$B,$A8),COUNTIF(投手成績!$B:$B,$A8)) -> 1
A9: P00008 | B9: Fletcher Engelhardt | C9: 打者 | D9: 1B | E9: R | F9: L | G9: 35631 | H9: 201 | I9: 110 | J9: 2018 | K9: BAL | L9: =INDEX(球隊主檔!$C$2:$C$31,MATCH($K9,球隊主檔!$A$2:$A$31,0)) -> 巴爾的摩金鶯 | M9: =IF($C9="打者",COUNTIF(打擊成績!$B:$B,$A9),COUNTIF(投手成績!$B:$B,$A9)) -> 1
A10: P00009 | B10: Haruto Dunmore | C10: 打者 | D10: 1B | E10: R | F10: L | G10: 35171 | H10: 197 | I10: 90 | J10: 2018 | K10: WSN | L10: =INDEX(球隊主檔!$C$2:$C$31,MATCH($K10,球隊主檔!$A$2:$A$31,0)) -> 華盛頓國民 | M10: =IF($C10="打者",COUNTIF(打擊成績!$B:$B,$A10),COUNTIF(投手成績!$B:$B,$A10)) -> 3
A11: P00010 | B11: Everett Ingersoll | C11: 打者 | D11: 3B | E11: L | F11: R | G11: 35439 | H11: 193 | I11: 83 | J11: 2018 | K11: CIN | L11: =INDEX(球隊主檔!$C$2:$C$31,MATCH($K11,球隊主檔!$A$2:$A$31,0)) -> 辛辛那提紅人 | M11: =IF($C11="打者",COUNTIF(打擊成績!$B:$B,$A11),COUNTIF(投手成績!$B:$B,$A11)) -> 3
A12: P00011 | B12: Ulises Halloway | C12: 投手 | D12: SP | E12: R | F12: L | G12: 36295 | H12: 197 | I12: 109 | J12: 2020 | K12: BAL | L12: =INDEX(球隊主檔!$C$2:$C$31,MATCH($K12,球隊主檔!$A$2:$A$31,0)) -> 巴爾的摩金鶯 | M12: =IF($C12="打者",COUNTIF(打擊成績!$B:$B,$A12),COUNTIF(投手成績!$B:$B,$A12)) -> 3
A13: P00012 | B13: Emilio Blackwood | C13: 投手 | D13: SP | E13: R | F13: L | G13: 34367 | H13: 194 | I13: 111 | J13: 2016 | K13: BAL | L13: =INDEX(球隊主檔!$C$2:$C$31,MATCH($K13,球隊主檔!$A$2:$A$31,0)) -> 巴爾的摩金鶯 | M13: =IF($C13="打者",COUNTIF(打擊成績!$B:$B,$A13),COUNTIF(投手成績!$B:$B,$A13)) -> 3
... A749: P00748 | B749: Cedric Novotný | C749: 打者 | D749: C | E749: S | F749: R | G749: 37438 | H749: 193 | I749: 95 | J749: 2026 | K749: SFG | L749: =INDEX(球隊主檔!$C$2:$C$31,MATCH($K749,球隊主檔!$A$2:$A$31,0)) -> 舊金山巨人 | M749: =IF($C749="打者",COUNTIF(打擊成績!$B:$B,$A749),COUNTIF(投手成績!$B:$B,$A749)) -> 1

Sheet 打擊成績
A1: 球季 | B1: 球員代號 | C1: 球員姓名 | D1: 球隊代號 | E1: 球隊中文名 | F1: 聯盟 | G1: 該季守備位置 | H1: 球季年齡 | I1: 出賽數 | J1: 打席 | K1: 打數 | L1: 得分 | M1: 安打 | N1: 二壘打 | O1: 三壘打 | P1: 全壘打 | Q1: 打點 | R1: 保送 | S1: 三振 | T1: 觸身球 | U1: 高飛犧牲打 | V1: 盜壘成功 | W1: 盜壘失敗 | X1: 壘打數 | Y1: 打擊率 | Z1: 上壘率 | AA1: 長打率 | AB1: 整體攻擊指數 | AC1: 純長打率 | AD1: 場內安打率 | AE1: 保送率 | AF1: 三振率 | AG1: 是否合格打者
A2: 2024 | B2: P00001 | C2: =INDEX(球員主檔!$B$2:$B$749,MATCH($B2,球員主檔!$A$2:$A$749,0)) -> Leandro Yarbrough | D2: BAL | E2: =INDEX(球隊主檔!$C$2:$C$31,MATCH($D2,球隊主檔!$A$2:$A$31,0)) -> 巴爾的摩金鶯 | F2: =INDEX(球隊主檔!$D$2:$D$31,MATCH($D2,球隊主檔!$A$2:$A$31,0)) -> 美聯 | G2: CF | H2: =INT((DATE($A2,7,1)-INDEX(球員主檔!$G$2:$G$749,MATCH($B2,球員主檔!$A$2:$A$749,0)))/365.25) -> 27 | I2: 162 | J2: 698 | K2: 635 | L2: 89 | M2: 164 | N2: 23 | O2: 3 | P2: 36 | Q2: 130 | R2: 48 | S2: 205 | T2: 8 | U2: 7 | V2: 19 | W2: 5 | X2: =M2+N2+2*O2+3*P2 -> 301 | Y2: =IF(K2=0,0,M2/K2) -> 0.25826772 | Z2: =IF(K2+R2+T2+U2=0,0,(M2+R2+T2)/(K2+R2+T2+U2)) -> 0.31518625 | AA2: =IF(K2=0,0,X2/K2) -> 0.47401575 | AB2: =Z2+AA2 -> 0.78920199 | AC2: =AA2-Y2 -> 0.21574803 | AD2: =IF(K2-S2-P2+U2=0,0,(M2-P2)/(K2-S2-P2+U2)) -> 0.319202 | AE2: =IF(J2=0,0,R2/J2) -> 0.068767908 | AF2: =IF(J2=0,0,S2/J2) -> 0.29369628 | AG2: =IF(J2>=INDEX(球季參數!$E$2:$E$4,MATCH($A2,球季參數!$A$2:$A$4,0)),1,0) -> 1
A3: 2024 | B3: P00002 | C3: =INDEX(球員主檔!$B$2:$B$749,MATCH($B3,球員主檔!$A$2:$A$749,0)) -> Seonwoo Brightwell | D3: BAL | E3: =INDEX(球隊主檔!$C$2:$C$31,MATCH($D3,球隊主檔!$A$2:$A$31,0)) -> 巴爾的摩金鶯 | F3: =INDEX(球隊主檔!$D$2:$D$31,MATCH($D3,球隊主檔!$A$2:$A$31,0)) -> 美聯 | G3: RF | H3: =INT((DATE($A3,7,1)-INDEX(球員主檔!$G$2:$G$749,MATCH($B3,球員主檔!$A$2:$A$749,0)))/365.25) -> 28 | I3: 74 | J3: 302 | K3: 285 | L3: 25 | M3: 47 | N3: 18 | O3: 0 | P3: 10 | Q3: 30 | R3: 9 | S3: 87 | T3: 6 | U3: 2 | V3: 8 | W3: 1 | X3: =M3+N3+2*O3+3*P3 -> 95 | Y3: =IF(K3=0,0,M3/K3) -> 0.16491228 | Z3: =IF(K3+R3+T3+U3=0,0,(M3+R3+T3)/(K3+R3+T3+U3)) -> 0.20529801 | AA3: =IF(K3=0,0,X3/K3) -> 0.33333333 | AB3: =Z3+AA3 -> 0.53863135 | AC3: =AA3-Y3 -> 0.16842105 | AD3: =IF(K3-S3-P3+U3=0,0,(M3-P3)/(K3-S3-P3+U3)) -> 0.19473684 | AE3: =IF(J3=0,0,R3/J3) -> 0.029801325 | AF3: =IF(J3=0,0,S3/J3) -> 0.28807947 | AG3: =IF(J3>=INDEX(球季參數!$E$2:$E$4,MATCH($A3,球季參數!$A$2:$A$4,0)),1,0) -> 0
A4: 2024 | B4: P00003 | C4: =INDEX(球員主檔!$B$2:$B$749,MATCH($B4,球員主檔!$A$2:$A$749,0)) -> Jasper Iwasaki | D4: BAL | E4: =INDEX(球隊主檔!$C$2:$C$31,MATCH($D4,球隊主檔!$A$2:$A$31,0)) -> 巴爾的摩金鶯 | F4: =INDEX(球隊主檔!$D$2:$D$31,MATCH($D4,球隊主檔!$A$2:$A$31,0)) -> 美聯 | G4: 3B | H4: =INT((DATE($A4,7,1)-INDEX(球員主檔!$G$2:$G$749,MATCH($B4,球員主檔!$A$2:$A$749,0)))/365.25) -> 24 | I4: 146 | J4: 648 | K4: 599 | L4: 81 | M4: 149 | N4: 32 | O4: 4 | P4: 33 | Q4: 111 | R4: 42 | S4: 101 | T4: 3 | U4: 4 | V4: 15 | W4: 2 | X4: =M4+N4+2*O4+3*P4 -> 288 | Y4: =IF(K4=0,0,M4/K4) -> 0.24874791 | Z4: =IF(K4+R4+T4+U4=0,0,(M4+R4+T4)/(K4+R4+T4+U4)) -> 0.29938272 | AA4: =IF(K4=0,0,X4/K4) -> 0.48080134 | AB4: =Z4+AA4 -> 0.78018405 | AC4: =AA4-Y4 -> 0.23205342 | AD4: =IF(K4-S4-P4+U4=0,0,(M4-P4)/(K4-S4-P4+U4)) -> 0.24733475 | AE4: =IF(J4=0,0,R4/J4) -> 0.064814815 | AF4: =IF(J4=0,0,S4/J4) -> 0.1558642 | AG4: =IF(J4>=INDEX(球季參數!$E$2:$E$4,MATCH($A4,球季參數!$A$2:$A$4,0)),1,0) -> 1
A5: 2024 | B5: P00004 | C5: =INDEX(球員主檔!$B$2:$B$749,MATCH($B5,球員主檔!$A$2:$A$749,0)) -> Tristan Lindquist | D5: BAL | E5: =INDEX(球隊主檔!$C$2:$C$31,MATCH($D5,球隊主檔!$A$2:$A$31,0)) -> 巴爾的摩金鶯 | F5: =INDEX(球隊主檔!$D$2:$D$31,MATCH($D5,球隊主檔!$A$2:$A$31,0)) -> 美聯 | G5: LF | H5: =INT((DATE($A5,7,1)-INDEX(球員主檔!$G$2:$G$749,MATCH($B5,球員主檔!$A$2:$A$749,0)))/365.25) -> 23 | I5: 162 | J5: 663 | K5: 516 | L5: 72 | M5: 102 | N5: 24 | O5: 5 | P5: 26 | Q5: 87 | R5: 132 | S5: 162 | T5: 9 | U5: 6 | V5: 7 | W5: 2 | X5: =M5+N5+2*O5+3*P5 -> 214 | Y5: =IF(K5=0,0,M5/K5) -> 0.19767442 | Z5: =IF(K5+R5+T5+U5=0,0,(M5+R5+T5)/(K5+R5+T5+U5)) -> 0.36651584 | AA5: =IF(K5=0,0,X5/K5) -> 0.41472868 | AB5: =Z5+AA5 -> 0.78124452 | AC5: =AA5-Y5 -> 0.21705426 | AD5: =IF(K5-S5-P5+U5=0,0,(M5-P5)/(K5-S5-P5+U5)) -> 0.22754491 | AE5: =IF(J5=0,0,R5/J5) -> 0.19909502 | AF5: =IF(J5=0,0,S5/J5) -> 0.24434389 | AG5: =IF(J5>=INDEX(球季參數!$E$2:$E$4,MATCH($A5,球季參數!$A$2:$A$4,0)),1,0) -> 1
A6: 2024 | B6: P00005 | C6: =INDEX(球員主檔!$B$2:$B$749,MATCH($B6,球員主檔!$A$2:$A$749,0)) -> Dashiell Novotný | D6: BAL | E6: =INDEX(球隊主檔!$C$2:$C$31,MATCH($D6,球隊主檔!$A$2:$A$31,0)) -> 巴爾的摩金鶯 | F6: =INDEX(球隊主檔!$D$2:$D$31,MATCH($D6,球隊主檔!$A$2:$A$31,0)) -> 美聯 | G6: RF | H6: =INT((DATE($A6,7,1)-INDEX(球員主檔!$G$2:$G$749,MATCH($B6,球員主檔!$A$2:$A$749,0)))/365.25) -> 33 | I6: 146 | J6: 594 | K6: 540 | L6: 73 | M6: 126 | N6: 43 | O6: 4 | P6: 26 | Q6: 77 | R6: 49 | S6: 122 | T6: 2 | U6: 3 | V6: 14 | W6: 3 | X6: =M6+N6+2*O6+3*P6 -> 255 | Y6: =IF(K6=0,0,M6/K6) -> 0.23333333 | Z6: =IF(K6+R6+T6+U6=0,0,(M6+R6+T6)/(K6+R6+T6+U6)) -> 0.2979798 | AA6: =IF(K6=0,0,X6/K6) -> 0.47222222 | AB6: =Z6+AA6 -> 0.77020202 | AC6: =AA6-Y6 -> 0.23888889 | AD6: =IF(K6-S6-P6+U6=0,0,(M6-P6)/(K6-S6-P6+U6)) -> 0.25316456 | AE6: =IF(J6=0,0,R6/J6) -> 0.082491582 | AF6: =IF(J6=0,0,S6/J6) -> 0.20538721 | AG6: =IF(J6>=INDEX(球季參數!$E$2:$E$4,MATCH($A6,球季參數!$A$2:$A$4,0)),1,0) -> 1
A7: 2024 | B7: P00006 | C7: =INDEX(球員主檔!$B$2:$B$749,MATCH($B7,球員主檔!$A$2:$A$749,0)) -> Leandro Esquivel | D7: BAL | E7: =INDEX(球隊主檔!$C$2:$C$31,MATCH($D7,球隊主檔!$A$2:$A$31,0)) -> 巴爾的摩金鶯 | F7: =INDEX(球隊主檔!$D$2:$D$31,MATCH($D7,球隊主檔!$A$2:$A$31,0)) -> 美聯 | G7: SS | H7: =INT((DATE($A7,7,1)-INDEX(球員主檔!$G$2:$G$749,MATCH($B7,球員主檔!$A$2:$A$749,0)))/365.25) -> 27 | I7: 99 | J7: 447 | K7: 407 | L7: 58 | M7: 120 | N7: 13 | O7: 7 | P7: 13 | Q7: 59 | R7: 35 | S7: 55 | T7: 1 | U7: 4 | V7: 8 | W7: 2 | X7: =M7+N7+2*O7+3*P7 -> 186 | Y7: =IF(K7=0,0,M7/K7) -> 0.29484029 | Z7: =IF(K7+R7+T7+U7=0,0,(M7+R7+T7)/(K7+R7+T7+U7)) -> 0.34899329 | AA7: =IF(K7=0,0,X7/K7) -> 0.45700246 | AB7: =Z7+AA7 -> 0.80599575 | AC7: =AA7-Y7 -> 0.16216216 | AD7: =IF(K7-S7-P7+U7=0,0,(M7-P7)/(K7-S7-P7+U7)) -> 0.31195335 | AE7: =IF(J7=0,0,R7/J7) -> 0.078299776 | AF7: =IF(J7=0,0,S7/J7) -> 0.12304251 | AG7: =IF(J7>=INDEX(球季參數!$E$2:$E$4,MATCH($A7,球季參數!$A$2:$A$4,0)),1,0) -> 0
A8: 2024 | B8: P00007 | C8: =INDEX(球員主檔!$B$2:$B$749,MATCH($B8,球員主檔!$A$2:$A$749,0)) -> Sawyer Whitmore | D8: BAL | E8: =INDEX(球隊主檔!$C$2:$C$31,MATCH($D8,球隊主檔!$A$2:$A$31,0)) -> 巴爾的摩金鶯 | F8: =INDEX(球隊主檔!$D$2:$D$31,MATCH($D8,球隊主檔!$A$2:$A$31,0)) -> 美聯 | G8: 1B | H8: =INT((DATE($A8,7,1)-INDEX(球員主檔!$G$2:$G$749,MATCH($B8,球員主檔!$A$2:$A$749,0)))/365.25) -> 23 | I8: 113 | J8: 472 | K8: 403 | L8: 72 | M8: 127 | N8: 34 | O8: 5 | P8: 23 | Q8: 72 | R8: 57 | S8: 77 | T8: 10 | U8: 2 | V8: 8 | W8: 1 | X8: =M8+N8+2*O8+3*P8 -> 240 | Y8: =IF(K8=0,0,M8/K8) -> 0.31513648 | Z8: =IF(K8+R8+T8+U8=0,0,(M8+R8+T8)/(K8+R8+T8+U8)) -> 0.41101695 | AA8: =IF(K8=0,0,X8/K8) -> 0.5955335 | AB8: =Z8+AA8 -> 1.0065504 | AC8: =AA8-Y8 -> 0.28039702 | AD8: =IF(K8-S8-P8+U8=0,0,(M8-P8)/(K8-S8-P8+U8)) -> 0.34098361 | AE8: =IF(J8=0,0,R8/J8) -> 0.12076271 | AF8: =IF(J8=0,0,S8/J8) -> 0.16313559 | AG8: =IF(J8>=INDEX(球季參數!$E$2:$E$4,MATCH($A8,球季參數!$A$2:$A$4,0)),1,0) -> 0
A9: 2024 | B9: P00008 | C9: =INDEX(球員主檔!$B$2:$B$749,MATCH($B9,球員主檔!$A$2:$A$749,0)) -> Fletcher Engelhardt | D9: BAL | E9: =INDEX(球隊主檔!$C$2:$C$31,MATCH($D9,球隊主檔!$A$2:$A$31,0)) -> 巴爾的摩金鶯 | F9: =INDEX(球隊主檔!$D$2:$D$31,MATCH($D9,球隊主檔!$A$2:$A$31,0)) -> 美聯 | G9: 1B | H9: =INT((DATE($A9,7,1)-INDEX(球員主檔!$G$2:$G$749,MATCH($B9,球員主檔!$A$2:$A$749,0)))/365.25) -> 26 | I9: 100 | J9: 393 | K9: 350 | L9: 35 | M9: 63 | N9: 22 | O9: 1 | P9: 14 | Q9: 42 | R9: 34 | S9: 109 | T9: 6 | U9: 3 | V9: 7 | W9: 1 | X9: =M9+N9+2*O9+3*P9 -> 129 | Y9: =IF(K9=0,0,M9/K9) -> 0.18 | Z9: =IF(K9+R9+T9+U9=0,0,(M9+R9+T9)/(K9+R9+T9+U9)) -> 0.26208651 | AA9: =IF(K9=0,0,X9/K9) -> 0.36857143 | AB9: =Z9+AA9 -> 0.63065794 | AC9: =AA9-Y9 -> 0.18857143 | AD9: =IF(K9-S9-P9+U9=0,0,(M9-P9)/(K9-S9-P9+U9)) -> 0.21304348 | AE9: =IF(J9=0,0,R9/J9) -> 0.086513995 | AF9: =IF(J9=0,0,S9/J9) -> 0.27735369 | AG9: =IF(J9>=INDEX(球季參數!$E$2:$E$4,MATCH($A9,球季參數!$A$2:$A$4,0)),1,0) -> 0
A10: 2024 | B10: P00009 | C10: =INDEX(球員主檔!$B$2:$B$749,MATCH($B10,球員主檔!$A$2:$A$749,0)) -> Haruto Dunmore | D10: BAL | E10: =INDEX(球隊主檔!$C$2:$C$31,MATCH($D10,球隊主檔!$A$2:$A$31,0)) -> 巴爾的摩金鶯 | F10: =INDEX(球隊主檔!$D$2:$D$31,MATCH($D10,球隊主檔!$A$2:$A$31,0)) -> 美聯 | G10: 1B | H10: =INT((DATE($A10,7,1)-INDEX(球員主檔!$G$2:$G$749,MATCH($B10,球員主檔!$A$2:$A$749,0)))/365.25) -> 28 | I10: 82 | J10: 332 | K10: 300 | L10: 41 | M10: 85 | N10: 22 | O10: 8 | P10: 6 | Q10: 30 | R10: 28 | S10: 81 | T10: 2 | U10: 2 | V10: 14 | W10: 4 | X10: =M10+N10+2*O10+3*P10 -> 141 | Y10: =IF(K10=0,0,M10/K10) -> 0.28333333 | Z10: =IF(K10+R10+T10+U10=0,0,(M10+R10+T10)/(K10+R10+T10+U10)) -> 0.34638554 | AA10: =IF(K10=0,0,X10/K10) -> 0.47 | AB10: =Z10+AA10 -> 0.81638554 | AC10: =AA10-Y10 -> 0.18666667 | AD10: =IF(K10-S10-P10+U10=0,0,(M10-P10)/(K10-S10-P10+U10)) -> 0.36744186 | AE10: =IF(J10=0,0,R10/J10) -> 0.084337349 | AF10: =IF(J10=0,0,S10/J10) -> 0.2439759 | AG10: =IF(J10>=INDEX(球季參數!$E$2:$E$4,MATCH($A10,球季參數!$A$2:$A$4,0)),1,0) -> 0
A11: 2024 | B11: P00010 | C11: =INDEX(球員主檔!$B$2:$B$749,MATCH($B11,球員主檔!$A$2:$A$749,0)) -> Everett Ingersoll | D11: BAL | E11: =INDEX(球隊主檔!$C$2:$C$31,MATCH($D11,球隊主檔!$A$2:$A$31,0)) -> 巴爾的摩金鶯 | F11: =INDEX(球隊主檔!$D$2:$D$31,MATCH($D11,球隊主檔!$A$2:$A$31,0)) -> 美聯 | G11: 3B | H11: =INT((DATE($A11,7,1)-INDEX(球員主檔!$G$2:$G$749,MATCH($B11,球員主檔!$A$2:$A$749,0)))/365.25) -> 27 | I11: 82 | J11: 333 | K11: 317 | L11: 39 | M11: 81 | N11: 21 | O11: 3 | P11: 8 | Q11: 35 | R11: 12 | S11: 65 | T11: 3 | U11: 1 | V11: 6 | W11: 1 | X11: =M11+N11+2*O11+3*P11 -> 132 | Y11: =IF(K11=0,0,M11/K11) -> 0.2555205 | Z11: =IF(K11+R11+T11+U11=0,0,(M11+R11+T11)/(K11+R11+T11+U11)) -> 0.28828829 | AA11: =IF(K11=0,0,X11/K11) -> 0.41640379 | AB11: =Z11+AA11 -> 0.70469207 | AC11: =AA11-Y11 -> 0.16088328 | AD11: =IF(K11-S11-P11+U11=0,0,(M11-P11)/(K11-S11-P11+U11)) -> 0.29795918 | AE11: =IF(J11=0,0,R11/J11) -> 0.036036036 | AF11: =IF(J11=0,0,S11/J11) -> 0.1951952 | AG11: =IF(J11>=INDEX(球季參數!$E$2:$E$4,MATCH($A11,球季參數!$A$2:$A$4,0)),1,0) -> 0
A12: 2024 | B12: P00021 | C12: =INDEX(球員主檔!$B$2:$B$749,MATCH($B12,球員主檔!$A$2:$A$749,0)) -> Leandro Castellón | D12: BOS | E12: =INDEX(球隊主檔!$C$2:$C$31,MATCH($D12,球隊主檔!$A$2:$A$31,0)) -> 波士頓紅襪 | F12: =INDEX(球隊主檔!$D$2:$D$31,MATCH($D12,球隊主檔!$A$2:$A$31,0)) -> 美聯 | G12: RF | H12: =INT((DATE($A12,7,1)-INDEX(球員主檔!$G$2:$G$749,MATCH($B12,球員主檔!$A$2:$A$749,0)))/365.25) -> 24 | I12: 62 | J12: 273 | K12: 240 | L12: 26 | M12: 51 | N12: 13 | O12: 10 | P12: 7 | Q12: 27 | R12: 28 | S12: 55 | T12: 3 | U12: 2 | V12: 5 | W12: 1 | X12: =M12+N12+2*O12+3*P12 -> 105 | Y12: =IF(K12=0,0,M12/K12) -> 0.2125 | Z12: =IF(K12+R12+T12+U12=0,0,(M12+R12+T12)/(K12+R12+T12+U12)) -> 0.3003663 | AA12: =IF(K12=0,0,X12/K12) -> 0.4375 | AB12: =Z12+AA12 -> 0.7378663 | AC12: =AA12-Y12 -> 0.225 | AD12: =IF(K12-S12-P12+U12=0,0,(M12-P12)/(K12-S12-P12+U12)) -> 0.24444444 | AE12: =IF(J12=0,0,R12/J12) -> 0.1025641 | AF12: =IF(J12=0,0,S12/J12) -> 0.2014652 | AG12: =IF(J12>=INDEX(球季參數!$E$2:$E$4,MATCH($A12,球季參數!$A$2:$A$4,0)),1,0) -> 0
A13: 2024 | B13: P00022 | C13: =INDEX(球員主檔!$B$2:$B$749,MATCH($B13,球員主檔!$A$2:$A$749,0)) -> Lucien Nordstrom | D13: BOS | E13: =INDEX(球隊主檔!$C$2:$C$31,MATCH($D13,球隊主檔!$A$2:$A$31,0)) -> 波士頓紅襪 | F13: =INDEX(球隊主檔!$D$2:$D$31,MATCH($D13,球隊主檔!$A$2:$A$31,0)) -> 美聯 | G13: SS | H13: =INT((DATE($A13,7,1)-INDEX(球員主檔!$G$2:$G$749,MATCH($B13,球員主檔!$A$2:$A$749,0)))/365.25) -> 23 | I13: 162 | J13: 679 | K13: 601 | L13: 101 | M13: 149 | N13: 30 | O13: 12 | P13: 47 | Q13: 140 | R13: 73 | S13: 149 | T13: 2 | U13: 3 | V13: 26 | W13: 5 | X13: =M13+N13+2*O13+3*P13 -> 344 | Y13: =IF(K13=0,0,M13/K13) -> 0.24792013 | Z13: =IF(K13+R13+T13+U13=0,0,(M13+R13+T13)/(K13+R13+T13+U13)) -> 0.32989691 | AA13: =IF(K13=0,0,X13/K13) -> 0.57237937 | AB13: =Z13+AA13 -> 0.90227627 | AC13: =AA13-Y13 -> 0.32445923 | AD13: =IF(K13-S13-P13+U13=0,0,(M13-P13)/(K13-S13-P13+U13)) -> 0.25 | AE13: =IF(J13=0,0,R13/J13) -> 0.10751105 | AF13: =IF(J13=0,0,S13/J13) -> 0.21944035 | AG13: =IF(J13>=INDEX(球季參數!$E$2:$E$4,MATCH($A13,球季參數!$A$2:$A$4,0)),1,0) -> 1
... A901: 2026 | B901: P00590 | C901: =INDEX(球員主檔!$B$2:$B$749,MATCH($B901,球員主檔!$A$2:$A$749,0)) -> Benedikt Halloway | D901: SFG | E901: =INDEX(球隊主檔!$C$2:$C$31,MATCH($D901,球隊主檔!$A$2:$A$31,0)) -> 舊金山巨人 | F901: =INDEX(球隊主檔!$D$2:$D$31,MATCH($D901,球隊主檔!$A$2:$A$31,0)) -> 國聯 | G901: 3B | H901: =INT((DATE($A901,7,1)-INDEX(球員主檔!$G$2:$G$749,MATCH($B901,球員主檔!$A$2:$A$749,0)))/365.25) -> 28 | I901: 41 | J901: 166 | K901: 151 | L901: 20 | M901: 40 | N901: 18 | O901: 1 | P901: 4 | Q901: 18 | R901: 12 | S901: 47 | T901: 3 | U901: 0 | V901: 4 | W901: 1 | X901: =M901+N901+2*O901+3*P901 -> 72 | Y901: =IF(K901=0,0,M901/K901) -> 0.26490066 | Z901: =IF(K901+R901+T901+U901=0,0,(M901+R901+T901)/(K901+R901+T901+U901)) -> 0.3313253 | AA901: =IF(K901=0,0,X901/K901) -> 0.47682119 | AB901: =Z901+AA901 -> 0.80814649 | AC901: =AA901-Y901 -> 0.21192053 | AD901: =IF(K901-S901-P901+U901=0,0,(M901-P901)/(K901-S901-P901+U901)) -> 0.36 | AE901: =IF(J901=0,0,R901/J901) -> 0.072289157 | AF901: =IF(J901=0,0,S901/J901) -> 0.28313253 | AG901: =IF(J901>=INDEX(球季參數!$E$2:$E$4,MATCH($A901,球季參數!$A$2:$A$4,0)),1,0) -> 0

Sheet 投手成績
A1: 球季 | B1: 球員代號 | C1: 球員姓名 | D1: 球隊代號 | E1: 球隊中文名 | F1: 聯盟 | G1: 投手角色 | H1: 球季年齡 | I1: 勝投 | J1: 敗投 | K1: 救援成功 | L1: 中繼成功 | M1: 出賽數 | N1: 先發場次 | O1: 投球出局數 | P1: 投球局數 | Q1: 局數顯示 | R1: 被安打 | S1: 失分 | T1: 自責分 | U1: 被全壘打 | V1: 保送 | W1: 三振 | X1: 觸身球 | Y1: 防禦率 | Z1: 每局被上壘率 | AA1: 每九局三振 | AB1: 每九局保送 | AC1: 三振保送比 | AD1: 獨立投球防禦率 | AE1: 是否合格投手
A2: 2024 | B2: P00011 | C2: =INDEX(球員主檔!$B$2:$B$749,MATCH($B2,球員主檔!$A$2:$A$749,0)) -> Ulises Halloway | D2: BAL | E2: =INDEX(球隊主檔!$C$2:$C$31,MATCH($D2,球隊主檔!$A$2:$A$31,0)) -> 巴爾的摩金鶯 | F2: =INDEX(球隊主檔!$D$2:$D$31,MATCH($D2,球隊主檔!$A$2:$A$31,0)) -> 美聯 | G2: SP | H2: =INT((DATE($A2,7,1)-INDEX(球員主檔!$G$2:$G$749,MATCH($B2,球員主檔!$A$2:$A$749,0)))/365.25) -> 25 | I2: 9 | J2: 4 | K2: 0 | L2: 0 | M2: 22 | N2: 22 | O2: 357 | P2: =O2/3 -> 119 | Q2: =INT(O2/3)&"."&MOD(O2,3) -> 119.0 | R2: 98 | S2: 52 | T2: 49 | U2: 10 | V2: 32 | W2: 112 | X2: 7 | Y2: =IF(O2=0,0,T2*27/O2) -> 3.7058824 | Z2: =IF(P2=0,0,(V2+R2)/P2) -> 1.092437 | AA2: =IF(O2=0,0,W2*27/O2) -> 8.4705882 | AB2: =IF(O2=0,0,V2*27/O2) -> 2.4201681 | AC2: =IF(V2=0,0,W2/V2) -> 3.5 | AD2: =IF(P2=0,0,(13*U2+3*(V2+X2)-2*W2)/P2+INDEX(球季參數!$C$2:$C$4,MATCH($A2,球季參數!$A$2:$A$4,0))) -> 3.3232773 | AE2: =IF(P2>=INDEX(球季參數!$F$2:$F$4,MATCH($A2,球季參數!$A$2:$A$4,0)),1,0) -> 0
A3: 2024 | B3: P00012 | C3: =INDEX(球員主檔!$B$2:$B$749,MATCH($B3,球員主檔!$A$2:$A$749,0)) -> Emilio Blackwood | D3: BAL | E3: =INDEX(球隊主檔!$C$2:$C$31,MATCH($D3,球隊主檔!$A$2:$A$31,0)) -> 巴爾的摩金鶯 | F3: =INDEX(球隊主檔!$D$2:$D$31,MATCH($D3,球隊主檔!$A$2:$A$31,0)) -> 美聯 | G3: SP | H3: =INT((DATE($A3,7,1)-INDEX(球員主檔!$G$2:$G$749,MATCH($B3,球員主檔!$A$2:$A$749,0)))/365.25) -> 30 | I3: 6 | J3: 6 | K3: 0 | L3: 0 | M3: 16 | N3: 16 | O3: 239 | P3: =O3/3 -> 79.666667 | Q3: =INT(O3/3)&"."&MOD(O3,3) -> 79.2 | R3: 69 | S3: 52 | T3: 46 | U3: 17 | V3: 34 | W3: 76 | X3: 2 | Y3: =IF(O3=0,0,T3*27/O3) -> 5.1966527 | Z3: =IF(P3=0,0,(V3+R3)/P3) -> 1.292887 | AA3: =IF(O3=0,0,W3*27/O3) -> 8.5857741 | AB3: =IF(O3=0,0,V3*27/O3) -> 3.8410042 | AC3: =IF(V3=0,0,W3/V3) -> 2.2352941 | AD3: =IF(P3=0,0,(13*U3+3*(V3+X3)-2*W3)/P3+INDEX(球季參數!$C$2:$C$4,MATCH($A3,球季參數!$A$2:$A$4,0))) -> 5.3517573 | AE3: =IF(P3>=INDEX(球季參數!$F$2:$F$4,MATCH($A3,球季參數!$A$2:$A$4,0)),1,0) -> 0
A4: 2024 | B4: P00013 | C4: =INDEX(球員主檔!$B$2:$B$749,MATCH($B4,球員主檔!$A$2:$A$749,0)) -> Holden Zielinski | D4: BAL | E4: =INDEX(球隊主檔!$C$2:$C$31,MATCH($D4,球隊主檔!$A$2:$A$31,0)) -> 巴爾的摩金鶯 | F4: =INDEX(球隊主檔!$D$2:$D$31,MATCH($D4,球隊主檔!$A$2:$A$31,0)) -> 美聯 | G4: SP | H4: =INT((DATE($A4,7,1)-INDEX(球員主檔!$G$2:$G$749,MATCH($B4,球員主檔!$A$2:$A$749,0)))/365.25) -> 27 | I4: 5 | J4: 2 | K4: 0 | L4: 0 | M4: 12 | N4: 12 | O4: 229 | P4: =O4/3 -> 76.333333 | Q4: =INT(O4/3)&"."&MOD(O4,3) -> 76.1 | R4: 54 | S4: 29 | T4: 28 | U4: 10 | V4: 20 | W4: 82 | X4: 1 | Y4: =IF(O4=0,0,T4*27/O4) -> 3.30131 | Z4: =IF(P4=0,0,(V4+R4)/P4) -> 0.96943231 | AA4: =IF(O4=0,0,W4*27/O4) -> 9.6681223 | AB4: =IF(O4=0,0,V4*27/O4) -> 2.3580786 | AC4: =IF(V4=0,0,W4/V4) -> 4.1 | AD4: =IF(P4=0,0,(13*U4+3*(V4+X4)-2*W4)/P4+INDEX(球季參數!$C$2:$C$4,MATCH($A4,球季參數!$A$2:$A$4,0))) -> 3.5099127 | AE4: =IF(P4>=INDEX(球季參數!$F$2:$F$4,MATCH($A4,球季參數!$A$2:$A$4,0)),1,0) -> 0
A5: 2024 | B5: P00014 | C5: =INDEX(球員主檔!$B$2:$B$749,MATCH($B5,球員主檔!$A$2:$A$749,0)) -> Augustin Halloway | D5: BAL | E5: =INDEX(球隊主檔!$C$2:$C$31,MATCH($D5,球隊主檔!$A$2:$A$31,0)) -> 巴爾的摩金鶯 | F5: =INDEX(球隊主檔!$D$2:$D$31,MATCH($D5,球隊主檔!$A$2:$A$31,0)) -> 美聯 | G5: SP | H5: =INT((DATE($A5,7,1)-INDEX(球員主檔!$G$2:$G$749,MATCH($B5,球員主檔!$A$2:$A$749,0)))/365.25) -> 24 | I5: 12 | J5: 6 | K5: 0 | L5: 0 | M5: 28 | N5: 28 | O5: 533 | P5: =O5/3 -> 177.66667 | Q5: =INT(O5/3)&"."&MOD(O5,3) -> 177.2 | R5: 136 | S5: 82 | T5: 74 | U5: 20 | V5: 69 | W5: 169 | X5: 3 | Y5: =IF(O5=0,0,T5*27/O5) -> 3.7485929 | Z5: =IF(P5=0,0,(V5+R5)/P5) -> 1.1538462 | AA5: =IF(O5=0,0,W5*27/O5) -> 8.5609756 | AB5: =IF(O5=0,0,V5*27/O5) -> 3.4953096 | AC5: =IF(V5=0,0,W5/V5) -> 2.4492754 | AD5: =IF(P5=0,0,(13*U5+3*(V5+X5)-2*W5)/P5+INDEX(球季參數!$C$2:$C$4,MATCH($A5,球季參數!$A$2:$A$4,0))) -> 3.9067355 | AE5: =IF(P5>=INDEX(球季參數!$F$2:$F$4,MATCH($A5,球季參數!$A$2:$A$4,0)),1,0) -> 1
A6: 2024 | B6: P00015 | C6: =INDEX(球員主檔!$B$2:$B$749,MATCH($B6,球員主檔!$A$2:$A$749,0)) -> Dashiell Oyelaran | D6: BAL | E6: =INDEX(球隊主檔!$C$2:$C$31,MATCH($D6,球隊主檔!$A$2:$A$31,0)) -> 巴爾的摩金鶯 | F6: =INDEX(球隊主檔!$D$2:$D$31,MATCH($D6,球隊主檔!$A$2:$A$31,0)) -> 美聯 | G6: SP | H6: =INT((DATE($A6,7,1)-INDEX(球員主檔!$G$2:$G$749,MATCH($B6,球員主檔!$A$2:$A$749,0)))/365.25) -> 28 | I6: 11 | J6: 12 | K6: 0 | L6: 0 | M6: 32 | N6: 32 | O6: 492 | P6: =O6/3 -> 164 | Q6: =INT(O6/3)&"."&MOD(O6,3) -> 164.0 | R6: 140 | S6: 90 | T6: 85 | U6: 21 | V6: 59 | W6: 145 | X6: 4 | Y6: =IF(O6=0,0,T6*27/O6) -> 4.6646341 | Z6: =IF(P6=0,0,(V6+R6)/P6) -> 1.2134146 | AA6: =IF(O6=0,0,W6*27/O6) -> 7.9573171 | AB6: =IF(O6=0,0,V6*27/O6) -> 3.2378049 | AC6: =IF(V6=0,0,W6/V6) -> 2.4576271 | AD6: =IF(P6=0,0,(13*U6+3*(V6+X6)-2*W6)/P6+INDEX(球季參數!$C$2:$C$4,MATCH($A6,球季參數!$A$2:$A$4,0))) -> 4.1787805 | AE6: =IF(P6>=INDEX(球季參數!$F$2:$F$4,MATCH($A6,球季參數!$A$2:$A$4,0)),1,0) -> 1
A7: 2024 | B7: P00016 | C7: =INDEX(球員主檔!$B$2:$B$749,MATCH($B7,球員主檔!$A$2:$A$749,0)) -> Jasper Novotný | D7: BAL | E7: =INDEX(球隊主檔!$C$2:$C$31,MATCH($D7,球隊主檔!$A$2:$A$31,0)) -> 巴爾的摩金鶯 | F7: =INDEX(球隊主檔!$D$2:$D$31,MATCH($D7,球隊主檔!$A$2:$A$31,0)) -> 美聯 | G7: RP | H7: =INT((DATE($A7,7,1)-INDEX(球員主檔!$G$2:$G$749,MATCH($B7,球員主檔!$A$2:$A$749,0)))/365.25) -> 30 | I7: 5 | J7: 8 | K7: 0 | L7: 17 | M7: 57 | N7: 0 | O7: 173 | P7: =O7/3 -> 57.666667 | Q7: =INT(O7/3)&"."&MOD(O7,3) -> 57.2 | R7: 46 | S7: 29 | T7: 27 | U7: 5 | V7: 17 | W7: 67 | X7: 1 | Y7: =IF(O7=0,0,T7*27/O7) -> 4.2138728 | Z7: =IF(P7=0,0,(V7+R7)/P7) -> 1.0924855 | AA7: =IF(O7=0,0,W7*27/O7) -> 10.456647 | AB7: =IF(O7=0,0,V7*27/O7) -> 2.6531792 | AC7: =IF(V7=0,0,W7/V7) -> 3.9411765 | AD7: =IF(P7=0,0,(13*U7+3*(V7+X7)-2*W7)/P7+INDEX(球季參數!$C$2:$C$4,MATCH($A7,球季參數!$A$2:$A$4,0))) -> 2.8698844 | AE7: =IF(P7>=INDEX(球季參數!$F$2:$F$4,MATCH($A7,球季參數!$A$2:$A$4,0)),1,0) -> 0
A8: 2024 | B8: P00017 | C8: =INDEX(球員主檔!$B$2:$B$749,MATCH($B8,球員主檔!$A$2:$A$749,0)) -> Thiago Gallimore | D8: BAL | E8: =INDEX(球隊主檔!$C$2:$C$31,MATCH($D8,球隊主檔!$A$2:$A$31,0)) -> 巴爾的摩金鶯 | F8: =INDEX(球隊主檔!$D$2:$D$31,MATCH($D8,球隊主檔!$A$2:$A$31,0)) -> 美聯 | G8: RP | H8: =INT((DATE($A8,7,1)-INDEX(球員主檔!$G$2:$G$749,MATCH($B8,球員主檔!$A$2:$A$749,0)))/365.25) -> 26 | I8: 7 | J8: 8 | K8: 6 | L8: 32 | M8: 66 | N8: 0 | O8: 222 | P8: =O8/3 -> 74 | Q8: =INT(O8/3)&"."&MOD(O8,3) -> 74.0 | R8: 51 | S8: 25 | T8: 24 | U8: 8 | V8: 16 | W8: 67 | X8: 3 | Y8: =IF(O8=0,0,T8*27/O8) -> 2.9189189 | Z8: =IF(P8=0,0,(V8+R8)/P8) -> 0.90540541 | AA8: =IF(O8=0,0,W8*27/O8) -> 8.1486486 | AB8: =IF(O8=0,0,V8*27/O8) -> 1.9459459 | AC8: =IF(V8=0,0,W8/V8) -> 4.1875 | AD8: =IF(P8=0,0,(13*U8+3*(V8+X8)-2*W8)/P8+INDEX(球季參數!$C$2:$C$4,MATCH($A8,球季參數!$A$2:$A$4,0))) -> 3.4948649 | AE8: =IF(P8>=INDEX(球季參數!$F$2:$F$4,MATCH($A8,球季參數!$A$2:$A$4,0)),1,0) -> 0
A9: 2024 | B9: P00018 | C9: =INDEX(球員主檔!$B$2:$B$749,MATCH($B9,球員主檔!$A$2:$A$749,0)) -> Thiago Uchendu | D9: BAL | E9: =INDEX(球隊主檔!$C$2:$C$31,MATCH($D9,球隊主檔!$A$2:$A$31,0)) -> 巴爾的摩金鶯 | F9: =INDEX(球隊主檔!$D$2:$D$31,MATCH($D9,球隊主檔!$A$2:$A$31,0)) -> 美聯 | G9: RP | H9: =INT((DATE($A9,7,1)-INDEX(球員主檔!$G$2:$G$749,MATCH($B9,球員主檔!$A$2:$A$749,0)))/365.25) -> 29 | I9: 3 | J9: 1 | K9: 3 | L9: 31 | M9: 44 | N9: 0 | O9: 125 | P9: =O9/3 -> 41.666667 | Q9: =INT(O9/3)&"."&MOD(O9,3) -> 41.2 | R9: 35 | S9: 21 | T9: 21 | U9: 10 | V9: 14 | W9: 40 | X9: 1 | Y9: =IF(O9=0,0,T9*27/O9) -> 4.536 | Z9: =IF(P9=0,0,(V9+R9)/P9) -> 1.176 | AA9: =IF(O9=0,0,W9*27/O9) -> 8.64 | AB9: =IF(O9=0,0,V9*27/O9) -> 3.024 | AC9: =IF(V9=0,0,W9/V9) -> 2.8571429 | AD9: =IF(P9=0,0,(13*U9+3*(V9+X9)-2*W9)/P9+INDEX(球季參數!$C$2:$C$4,MATCH($A9,球季參數!$A$2:$A$4,0))) -> 5.41 | AE9: =IF(P9>=INDEX(球季參數!$F$2:$F$4,MATCH($A9,球季參數!$A$2:$A$4,0)),1,0) -> 0
A10: 2024 | B10: P00019 | C10: =INDEX(球員主檔!$B$2:$B$749,MATCH($B10,球員主檔!$A$2:$A$749,0)) -> Desmond Tremblay | D10: BAL | E10: =INDEX(球隊主檔!$C$2:$C$31,MATCH($D10,球隊主檔!$A$2:$A$31,0)) -> 巴爾的摩金鶯 | F10: =INDEX(球隊主檔!$D$2:$D$31,MATCH($D10,球隊主檔!$A$2:$A$31,0)) -> 美聯 | G10: RP | H10: =INT((DATE($A10,7,1)-INDEX(球員主檔!$G$2:$G$749,MATCH($B10,球員主檔!$A$2:$A$749,0)))/365.25) -> 25 | I10: 4 | J10: 4 | K10: 1 | L10: 19 | M10: 74 | N10: 0 | O10: 236 | P10: =O10/3 -> 78.666667 | Q10: =INT(O10/3)&"."&MOD(O10,3) -> 78.2 | R10: 71 | S10: 42 | T10: 39 | U10: 8 | V10: 24 | W10: 80 | X10: 3 | Y10: =IF(O10=0,0,T10*27/O10) -> 4.4618644 | Z10: =IF(P10=0,0,(V10+R10)/P10) -> 1.2076271 | AA10: =IF(O10=0,0,W10*27/O10) -> 9.1525424 | AB10: =IF(O10=0,0,V10*27/O10) -> 2.7457627 | AC10: =IF(V10=0,0,W10/V10) -> 3.3333333 | AD10: =IF(P10=0,0,(13*U10+3*(V10+X10)-2*W10)/P10+INDEX(球季參數!$C$2:$C$4,MATCH($A10,球季參數!$A$2:$A$4,0))) -> 3.4477966 | AE10: =IF(P10>=INDEX(球季參數!$F$2:$F$4,MATCH($A10,球季參數!$A$2:$A$4,0)),1,0) -> 0
A11: 2024 | B11: P00020 | C11: =INDEX(球員主檔!$B$2:$B$749,MATCH($B11,球員主檔!$A$2:$A$749,0)) -> Kellan Jernigan | D11: BAL | E11: =INDEX(球隊主檔!$C$2:$C$31,MATCH($D11,球隊主檔!$A$2:$A$31,0)) -> 巴爾的摩金鶯 | F11: =INDEX(球隊主檔!$D$2:$D$31,MATCH($D11,球隊主檔!$A$2:$A$31,0)) -> 美聯 | G11: RP | H11: =INT((DATE($A11,7,1)-INDEX(球員主檔!$G$2:$G$749,MATCH($B11,球員主檔!$A$2:$A$749,0)))/365.25) -> 27 | I11: 5 | J11: 0 | K11: 1 | L11: 25 | M11: 51 | N11: 0 | O11: 162 | P11: =O11/3 -> 54 | Q11: =INT(O11/3)&"."&MOD(O11,3) -> 54.0 | R11: 40 | S11: 16 | T11: 16 | U11: 8 | V11: 11 | W11: 46 | X11: 1 | Y11: =IF(O11=0,0,T11*27/O11) -> 2.6666667 | Z11: =IF(P11=0,0,(V11+R11)/P11) -> 0.94444444 | AA11: =IF(O11=0,0,W11*27/O11) -> 7.6666667 | AB11: =IF(O11=0,0,V11*27/O11) -> 1.8333333 | AC11: =IF(V11=0,0,W11/V11) -> 4.1818182 | AD11: =IF(P11=0,0,(13*U11+3*(V11+X11)-2*W11)/P11+INDEX(球季參數!$C$2:$C$4,MATCH($A11,球季參數!$A$2:$A$4,0))) -> 4.0188889 | AE11: =IF(P11>=INDEX(球季參數!$F$2:$F$4,MATCH($A11,球季參數!$A$2:$A$4,0)),1,0) -> 0
A12: 2024 | B12: P00031 | C12: =INDEX(球員主檔!$B$2:$B$749,MATCH($B12,球員主檔!$A$2:$A$749,0)) -> Joaquín Ibarra | D12: BOS | E12: =INDEX(球隊主檔!$C$2:$C$31,MATCH($D12,球隊主檔!$A$2:$A$31,0)) -> 波士頓紅襪 | F12: =INDEX(球隊主檔!$D$2:$D$31,MATCH($D12,球隊主檔!$A$2:$A$31,0)) -> 美聯 | G12: SP | H12: =INT((DATE($A12,7,1)-INDEX(球員主檔!$G$2:$G$749,MATCH($B12,球員主檔!$A$2:$A$749,0)))/365.25) -> 32 | I12: 14 | J12: 4 | K12: 0 | L12: 0 | M12: 28 | N12: 28 | O12: 528 | P12: =O12/3 -> 176 | Q12: =INT(O12/3)&"."&MOD(O12,3) -> 176.0 | R12: 124 | S12: 57 | T12: 57 | U12: 33 | V12: 60 | W12: 213 | X12: 3 | Y12: =IF(O12=0,0,T12*27/O12) -> 2.9147727 | Z12: =IF(P12=0,0,(V12+R12)/P12) -> 1.0454545 | AA12: =IF(O12=0,0,W12*27/O12) -> 10.892045 | AB12: =IF(O12=0,0,V12*27/O12) -> 3.0681818 | AC12: =IF(V12=0,0,W12/V12) -> 3.55 | AD12: =IF(P12=0,0,(13*U12+3*(V12+X12)-2*W12)/P12+INDEX(球季參數!$C$2:$C$4,MATCH($A12,球季參數!$A$2:$A$4,0))) -> 4.2209091 | AE12: =IF(P12>=INDEX(球季參數!$F$2:$F$4,MATCH($A12,球季參數!$A$2:$A$4,0)),1,0) -> 1
A13: 2024 | B13: P00032 | C13: =INDEX(球員主檔!$B$2:$B$749,MATCH($B13,球員主檔!$A$2:$A$749,0)) -> Lorenzo Jaramillo | D13: BOS | E13: =INDEX(球隊主檔!$C$2:$C$31,MATCH($D13,球隊主檔!$A$2:$A$31,0)) -> 波士頓紅襪 | F13: =INDEX(球隊主檔!$D$2:$D$31,MATCH($D13,球隊主檔!$A$2:$A$31,0)) -> 美聯 | G13: SP | H13: =INT((DATE($A13,7,1)-INDEX(球員主檔!$G$2:$G$749,MATCH($B13,球員主檔!$A$2:$A$749,0)))/365.25) -> 28 | I13: 4 | J13: 4 | K13: 0 | L13: 0 | M13: 11 | N13: 11 | O13: 174 | P13: =O13/3 -> 58 | Q13: =INT(O13/3)&"."&MOD(O13,3) -> 58.0 | R13: 50 | S13: 33 | T13: 30 | U13: 11 | V13: 12 | W13: 56 | X13: 1 | Y13: =IF(O13=0,0,T13*27/O13) -> 4.6551724 | Z13: =IF(P13=0,0,(V13+R13)/P13) -> 1.0689655 | AA13: =IF(O13=0,0,W13*27/O13) -> 8.6896552 | AB13: =IF(O13=0,0,V13*27/O13) -> 1.862069 | AC13: =IF(V13=0,0,W13/V13) -> 4.6666667 | AD13: =IF(P13=0,0,(13*U13+3*(V13+X13)-2*W13)/P13+INDEX(球季參數!$C$2:$C$4,MATCH($A13,球季參數!$A$2:$A$4,0))) -> 4.3368966 | AE13: =IF(P13>=INDEX(球季參數!$F$2:$F$4,MATCH($A13,球季參數!$A$2:$A$4,0)),1,0) -> 0
... A901: 2026 | B901: P00600 | C901: =INDEX(球員主檔!$B$2:$B$749,MATCH($B901,球員主檔!$A$2:$A$749,0)) -> Lorenzo Novotný | D901: SFG | E901: =INDEX(球隊主檔!$C$2:$C$31,MATCH($D901,球隊主檔!$A$2:$A$31,0)) -> 舊金山巨人 | F901: =INDEX(球隊主檔!$D$2:$D$31,MATCH($D901,球隊主檔!$A$2:$A$31,0)) -> 國聯 | G901: RP | H901: =INT((DATE($A901,7,1)-INDEX(球員主檔!$G$2:$G$749,MATCH($B901,球員主檔!$A$2:$A$749,0)))/365.25) -> 31 | I901: 4 | J901: 8 | K901: 1 | L901: 11 | M901: 73 | N901: 0 | O901: 191 | P901: =O901/3 -> 63.666667 | Q901: =INT(O901/3)&"."&MOD(O901,3) -> 63.2 | R901: 53 | S901: 33 | T901: 31 | U901: 5 | V901: 20 | W901: 67 | X901: 2 | Y901: =IF(O901=0,0,T901*27/O901) -> 4.382199 | Z901: =IF(P901=0,0,(V901+R901)/P901) -> 1.1465969 | AA901: =IF(O901=0,0,W901*27/O901) -> 9.4712042 | AB901: =IF(O901=0,0,V901*27/O901) -> 2.8272251 | AC901: =IF(V901=0,0,W901/V901) -> 3.35 | AD901: =IF(P901=0,0,(13*U901+3*(V901+X901)-2*W901)/P901+INDEX(球季參數!$C$2:$C$4,MATCH($A901,球季參數!$A$2:$A$4,0))) -> 3.0328796 | AE901: =IF(P901>=INDEX(球季參數!$F$2:$F$4,MATCH($A901,球季參數!$A$2:$A$4,0)),1,0) -> 0

Sheet 球隊戰績
A1: 球季 | B1: 球隊代號 | C1: 球隊中文名 | D1: 聯盟 | E1: 分區 | F1: 勝場 | G1: 敗場 | H1: 勝率 | I1: 分區勝差 | J1: 得分 | K1: 失分 | L1: 得失分差 | M1: 畢氏勝率 | N1: 畢氏預期勝場 | O1: 實際減預期
A2: 2024 | B2: BAL | C2: =INDEX(球隊主檔!$C$2:$C$31,MATCH($B2,球隊主檔!$A$2:$A$31,0)) -> 巴爾的摩金鶯 | D2: =INDEX(球隊主檔!$D$2:$D$31,MATCH($B2,球隊主檔!$A$2:$A$31,0)) -> 美聯 | E2: =INDEX(球隊主檔!$E$2:$E$31,MATCH($B2,球隊主檔!$A$2:$A$31,0)) -> 美東 | F2: 83 | G2: =INDEX(球季參數!$B$2:$B$4,MATCH($A2,球季參數!$A$2:$A$4,0))-F2 -> 79 | H2: =IF(F2+G2=0,0,F2/(F2+G2)) -> 0.51234568 | I2: =(SUMPRODUCT(MAX(($A$2:$A$91=$A2)*($E$2:$E$91=$E2)*$F$2:$F$91))-F2+G2-SUMPRODUCT(MIN(($A$2:$A$91=$A2)*($E$2:$E$91=$E2)*$G$2:$G$91+(1-($A$2:$A$91=$A2)*($E$2:$E$91=$E2))*999)))/2 -> 5 | J2: 688 | K2: 640 | L2: =J2-K2 -> 48 | M2: =IF(POWER(J2,INDEX(球季參數!$D$2:$D$4,MATCH($A2,球季參數!$A$2:$A$4,0)))+POWER(K2,INDEX(球季參數!$D$2:$D$4,MATCH($A2,球季參數!$A$2:$A$4,0)))=0,0,POWER(J2,INDEX(球季參數!$D$2:$D$4,MATCH($A2,球季參數!$A$2:$A$4,0)))/(POWER(J2,INDEX(球季參數!$D$2:$D$4,MATCH($A2,球季參數!$A$2:$A$4,0)))+POWER(K2,INDEX(球季參數!$D$2:$D$4,MATCH($A2,球季參數!$A$2:$A$4,0))))) -> 0.53303849 | N2: =M2*(F2+G2) -> 86.352236 | O2: =F2-N2 -> -3.3522358
A3: 2024 | B3: BOS | C3: =INDEX(球隊主檔!$C$2:$C$31,MATCH($B3,球隊主檔!$A$2:$A$31,0)) -> 波士頓紅襪 | D3: =INDEX(球隊主檔!$D$2:$D$31,MATCH($B3,球隊主檔!$A$2:$A$31,0)) -> 美聯 | E3: =INDEX(球隊主檔!$E$2:$E$31,MATCH($B3,球隊主檔!$A$2:$A$31,0)) -> 美東 | F3: 88 | G3: =INDEX(球季參數!$B$2:$B$4,MATCH($A3,球季參數!$A$2:$A$4,0))-F3 -> 74 | H3: =IF(F3+G3=0,0,F3/(F3+G3)) -> 0.54320988 | I3: =(SUMPRODUCT(MAX(($A$2:$A$91=$A3)*($E$2:$E$91=$E3)*$F$2:$F$91))-F3+G3-SUMPRODUCT(MIN(($A$2:$A$91=$A3)*($E$2:$E$91=$E3)*$G$2:$G$91+(1-($A$2:$A$91=$A3)*($E$2:$E$91=$E3))*999)))/2 -> 0 | J3: 791 | K3: 732 | L3: =J3-K3 -> 59 | M3: =IF(POWER(J3,INDEX(球季參數!$D$2:$D$4,MATCH($A3,球季參數!$A$2:$A$4,0)))+POWER(K3,INDEX(球季參數!$D$2:$D$4,MATCH($A3,球季參數!$A$2:$A$4,0)))=0,0,POWER(J3,INDEX(球季參數!$D$2:$D$4,MATCH($A3,球季參數!$A$2:$A$4,0)))/(POWER(J3,INDEX(球季參數!$D$2:$D$4,MATCH($A3,球季參數!$A$2:$A$4,0)))+POWER(K3,INDEX(球季參數!$D$2:$D$4,MATCH($A3,球季參數!$A$2:$A$4,0))))) -> 0.53540488 | N3: =M3*(F3+G3) -> 86.735591 | O3: =F3-N3 -> 1.264409
A4: 2024 | B4: NYY | C4: =INDEX(球隊主檔!$C$2:$C$31,MATCH($B4,球隊主檔!$A$2:$A$31,0)) -> 紐約洋基 | D4: =INDEX(球隊主檔!$D$2:$D$31,MATCH($B4,球隊主檔!$A$2:$A$31,0)) -> 美聯 | E4: =INDEX(球隊主檔!$E$2:$E$31,MATCH($B4,球隊主檔!$A$2:$A$31,0)) -> 美東 | F4: 87 | G4: =INDEX(球季參數!$B$2:$B$4,MATCH($A4,球季參數!$A$2:$A$4,0))-F4 -> 75 | H4: =IF(F4+G4=0,0,F4/(F4+G4)) -> 0.53703704 | I4: =(SUMPRODUCT(MAX(($A$2:$A$91=$A4)*($E$2:$E$91=$E4)*$F$2:$F$91))-F4+G4-SUMPRODUCT(MIN(($A$2:$A$91=$A4)*($E$2:$E$91=$E4)*$G$2:$G$91+(1-($A$2:$A$91=$A4)*($E$2:$E$91=$E4))*999)))/2 -> 1 | J4: 733 | K4: 662 | L4: =J4-K4 -> 71 | M4: =IF(POWER(J4,INDEX(球季參數!$D$2:$D$4,MATCH($A4,球季參數!$A$2:$A$4,0)))+POWER(K4,INDEX(球季參數!$D$2:$D$4,MATCH($A4,球季參數!$A$2:$A$4,0)))=0,0,POWER(J4,INDEX(球季參數!$D$2:$D$4,MATCH($A4,球季參數!$A$2:$A$4,0)))/(POWER(J4,INDEX(球季參數!$D$2:$D$4,MATCH($A4,球季參數!$A$2:$A$4,0)))+POWER(K4,INDEX(球季參數!$D$2:$D$4,MATCH($A4,球季參數!$A$2:$A$4,0))))) -> 0.54647562 | N4: =M4*(F4+G4) -> 88.52905 | O4: =F4-N4 -> -1.5290504
A5: 2024 | B5: TBR | C5: =INDEX(球隊主檔!$C$2:$C$31,MATCH($B5,球隊主檔!$A$2:$A$31,0)) -> 坦帕灣光芒 | D5: =INDEX(球隊主檔!$D$2:$D$31,MATCH($B5,球隊主檔!$A$2:$A$31,0)) -> 美聯 | E5: =INDEX(球隊主檔!$E$2:$E$31,MATCH($B5,球隊主檔!$A$2:$A$31,0)) -> 美東 | F5: 75 | G5: =INDEX(球季參數!$B$2:$B$4,MATCH($A5,球季參數!$A$2:$A$4,0))-F5 -> 87 | H5: =IF(F5+G5=0,0,F5/(F5+G5)) -> 0.46296296 | I5: =(SUMPRODUCT(MAX(($A$2:$A$91=$A5)*($E$2:$E$91=$E5)*$F$2:$F$91))-F5+G5-SUMPRODUCT(MIN(($A$2:$A$91=$A5)*($E$2:$E$91=$E5)*$G$2:$G$91+(1-($A$2:$A$91=$A5)*($E$2:$E$91=$E5))*999)))/2 -> 13 | J5: 666 | K5: 752 | L5: =J5-K5 -> -86 | M5: =IF(POWER(J5,INDEX(球季參數!$D$2:$D$4,MATCH($A5,球季參數!$A$2:$A$4,0)))+POWER(K5,INDEX(球季參數!$D$2:$D$4,MATCH($A5,球季參數!$A$2:$A$4,0)))=0,0,POWER(J5,INDEX(球季參數!$D$2:$D$4,MATCH($A5,球季參數!$A$2:$A$4,0)))/(POWER(J5,INDEX(球季參數!$D$2:$D$4,MATCH($A5,球季參數!$A$2:$A$4,0)))+POWER(K5,INDEX(球季參數!$D$2:$D$4,MATCH($A5,球季參數!$A$2:$A$4,0))))) -> 0.44466573 | N5: =M5*(F5+G5) -> 72.035849 | O5: =F5-N5 -> 2.9641512
A6: 2024 | B6: TOR | C6: =INDEX(球隊主檔!$C$2:$C$31,MATCH($B6,球隊主檔!$A$2:$A$31,0)) -> 多倫多藍鳥 | D6: =INDEX(球隊主檔!$D$2:$D$31,MATCH($B6,球隊主檔!$A$2:$A$31,0)) -> 美聯 | E6: =INDEX(球隊主檔!$E$2:$E$31,MATCH($B6,球隊主檔!$A$2:$A$31,0)) -> 美東 | F6: 73 | G6: =INDEX(球季參數!$B$2:$B$4,MATCH($A6,球季參數!$A$2:$A$4,0))-F6 -> 89 | H6: =IF(F6+G6=0,0,F6/(F6+G6)) -> 0.45061728 | I6: =(SUMPRODUCT(MAX(($A$2:$A$91=$A6)*($E$2:$E$91=$E6)*$F$2:$F$91))-F6+G6-SUMPRODUCT(MIN(($A$2:$A$91=$A6)*($E$2:$E$91=$E6)*$G$2:$G$91+(1-($A$2:$A$91=$A6)*($E$2:$E$91=$E6))*999)))/2 -> 15 | J6: 728 | K6: 774 | L6: =J6-K6 -> -46 | M6: =IF(POWER(J6,INDEX(球季參數!$D$2:$D$4,MATCH($A6,球季參數!$A$2:$A$4,0)))+POWER(K6,INDEX(球季參數!$D$2:$D$4,MATCH($A6,球季參數!$A$2:$A$4,0)))=0,0,POWER(J6,INDEX(球季參數!$D$2:$D$4,MATCH($A6,球季參數!$A$2:$A$4,0)))/(POWER(J6,INDEX(球季參數!$D$2:$D$4,MATCH($A6,球季參數!$A$2:$A$4,0)))+POWER(K6,INDEX(球季參數!$D$2:$D$4,MATCH($A6,球季參數!$A$2:$A$4,0))))) -> 0.47199793 | N6: =M6*(F6+G6) -> 76.463664 | O6: =F6-N6 -> -3.4636644
A7: 2024 | B7: CWS | C7: =INDEX(球隊主檔!$C$2:$C$31,MATCH($B7,球隊主檔!$A$2:$A$31,0)) -> 芝加哥白襪 | D7: =INDEX(球隊主檔!$D$2:$D$31,MATCH($B7,球隊主檔!$A$2:$A$31,0)) -> 美聯 | E7: =INDEX(球隊主檔!$E$2:$E$31,MATCH($B7,球隊主檔!$A$2:$A$31,0)) -> 美中 | F7: 86 | G7: =INDEX(球季參數!$B$2:$B$4,MATCH($A7,球季參數!$A$2:$A$4,0))-F7 -> 76 | H7: =IF(F7+G7=0,0,F7/(F7+G7)) -> 0.5308642 | I7: =(SUMPRODUCT(MAX(($A$2:$A$91=$A7)*($E$2:$E$91=$E7)*$F$2:$F$91))-F7+G7-SUMPRODUCT(MIN(($A$2:$A$91=$A7)*($E$2:$E$91=$E7)*$G$2:$G$91+(1-($A$2:$A$91=$A7)*($E$2:$E$91=$E7))*999)))/2 -> 9 | J7: 679 | K7: 628 | L7: =J7-K7 -> 51 | M7: =IF(POWER(J7,INDEX(球季參數!$D$2:$D$4,MATCH($A7,球季參數!$A$2:$A$4,0)))+POWER(K7,INDEX(球季參數!$D$2:$D$4,MATCH($A7,球季參數!$A$2:$A$4,0)))=0,0,POWER(J7,INDEX(球季參數!$D$2:$D$4,MATCH($A7,球季參數!$A$2:$A$4,0)))/(POWER(J7,INDEX(球季參數!$D$2:$D$4,MATCH($A7,球季參數!$A$2:$A$4,0)))+POWER(K7,INDEX(球季參數!$D$2:$D$4,MATCH($A7,球季參數!$A$2:$A$4,0))))) -> 0.53566139 | N7: =M7*(F7+G7) -> 86.777144 | O7: =F7-N7 -> -0.77714443
A8: 2024 | B8: CLE | C8: =INDEX(球隊主檔!$C$2:$C$31,MATCH($B8,球隊主檔!$A$2:$A$31,0)) -> 克里夫蘭守護者 | D8: =INDEX(球隊主檔!$D$2:$D$31,MATCH($B8,球隊主檔!$A$2:$A$31,0)) -> 美聯 | E8: =INDEX(球隊主檔!$E$2:$E$31,MATCH($B8,球隊主檔!$A$2:$A$31,0)) -> 美中 | F8: 80 | G8: =INDEX(球季參數!$B$2:$B$4,MATCH($A8,球季參數!$A$2:$A$4,0))-F8 -> 82 | H8: =IF(F8+G8=0,0,F8/(F8+G8)) -> 0.49382716 | I8: =(SUMPRODUCT(MAX(($A$2:$A$91=$A8)*($E$2:$E$91=$E8)*$F$2:$F$91))-F8+G8-SUMPRODUCT(MIN(($A$2:$A$91=$A8)*($E$2:$E$91=$E8)*$G$2:$G$91+(1-($A$2:$A$91=$A8)*($E$2:$E$91=$E8))*999)))/2 -> 15 | J8: 722 | K8: 720 | L8: =J8-K8 -> 2 | M8: =IF(POWER(J8,INDEX(球季參數!$D$2:$D$4,MATCH($A8,球季參數!$A$2:$A$4,0)))+POWER(K8,INDEX(球季參數!$D$2:$D$4,MATCH($A8,球季參數!$A$2:$A$4,0)))=0,0,POWER(J8,INDEX(球季參數!$D$2:$D$4,MATCH($A8,球季參數!$A$2:$A$4,0)))/(POWER(J8,INDEX(球季參數!$D$2:$D$4,MATCH($A8,球季參數!$A$2:$A$4,0)))+POWER(K8,INDEX(球季參數!$D$2:$D$4,MATCH($A8,球季參數!$A$2:$A$4,0))))) -> 0.50126907 | N8: =M8*(F8+G8) -> 81.205589 | O8: =F8-N8 -> -1.2055891
A9: 2024 | B9: DET | C9: =INDEX(球隊主檔!$C$2:$C$31,MATCH($B9,球隊主檔!$A$2:$A$31,0)) -> 底特律老虎 | D9: =INDEX(球隊主檔!$D$2:$D$31,MATCH($B9,球隊主檔!$A$2:$A$31,0)) -> 美聯 | E9: =INDEX(球隊主檔!$E$2:$E$31,MATCH($B9,球隊主檔!$A$2:$A$31,0)) -> 美中 | F9: 95 | G9: =INDEX(球季參數!$B$2:$B$4,MATCH($A9,球季參數!$A$2:$A$4,0))-F9 -> 67 | H9: =IF(F9+G9=0,0,F9/(F9+G9)) -> 0.58641975 | I9: =(SUMPRODUCT(MAX(($A$2:$A$91=$A9)*($E$2:$E$91=$E9)*$F$2:$F$91))-F9+G9-SUMPRODUCT(MIN(($A$2:$A$91=$A9)*($E$2:$E$91=$E9)*$G$2:$G$91+(1-($A$2:$A$91=$A9)*($E$2:$E$91=$E9))*999)))/2 -> 0 | J9: 801 | K9: 656 | L9: =J9-K9 -> 145 | M9: =IF(POWER(J9,INDEX(球季參數!$D$2:$D$4,MATCH($A9,球季參數!$A$2:$A$4,0)))+POWER(K9,INDEX(球季參數!$D$2:$D$4,MATCH($A9,球季參數!$A$2:$A$4,0)))=0,0,POWER(J9,INDEX(球季參數!$D$2:$D$4,MATCH($A9,球季參數!$A$2:$A$4,0)))/(POWER(J9,INDEX(球季參數!$D$2:$D$4,MATCH($A9,球季參數!$A$2:$A$4,0)))+POWER(K9,INDEX(球季參數!$D$2:$D$4,MATCH($A9,球季參數!$A$2:$A$4,0))))) -> 0.59035939 | N9: =M9*(F9+G9) -> 95.638222 | O9: =F9-N9 -> -0.63822183
A10: 2024 | B10: KCR | C10: =INDEX(球隊主檔!$C$2:$C$31,MATCH($B10,球隊主檔!$A$2:$A$31,0)) -> 堪薩斯市皇家 | D10: =INDEX(球隊主檔!$D$2:$D$31,MATCH($B10,球隊主檔!$A$2:$A$31,0)) -> 美聯 | E10: =INDEX(球隊主檔!$E$2:$E$31,MATCH($B10,球隊主檔!$A$2:$A$31,0)) -> 美中 | F10: 83 | G10: =INDEX(球季參數!$B$2:$B$4,MATCH($A10,球季參數!$A$2:$A$4,0))-F10 -> 79 | H10: =IF(F10+G10=0,0,F10/(F10+G10)) -> 0.51234568 | I10: =(SUMPRODUCT(MAX(($A$2:$A$91=$A10)*($E$2:$E$91=$E10)*$F$2:$F$91))-F10+G10-SUMPRODUCT(MIN(($A$2:$A$91=$A10)*($E$2:$E$91=$E10)*$G$2:$G$91+(1-($A$2:$A$91=$A10)*($E$2:$E$91=$E10))*999)))/2 -> 12 | J10: 702 | K10: 704 | L10: =J10-K10 -> -2 | M10: =IF(POWER(J10,INDEX(球季參數!$D$2:$D$4,MATCH($A10,球季參數!$A$2:$A$4,0)))+POWER(K10,INDEX(球季參數!$D$2:$D$4,MATCH($A10,球季參數!$A$2:$A$4,0)))=0,0,POWER(J10,INDEX(球季參數!$D$2:$D$4,MATCH($A10,球季參數!$A$2:$A$4,0)))/(POWER(J10,INDEX(球季參數!$D$2:$D$4,MATCH($A10,球季參數!$A$2:$A$4,0)))+POWER(K10,INDEX(球季參數!$D$2:$D$4,MATCH($A10,球季參數!$A$2:$A$4,0))))) -> 0.49869844 | N10: =M10*(F10+G10) -> 80.789147 | O10: =F10-N10 -> 2.2108532
A11: 2024 | B11: MIN | C11: =INDEX(球隊主檔!$C$2:$C$31,MATCH($B11,球隊主檔!$A$2:$A$31,0)) -> 明尼蘇達雙城 | D11: =INDEX(球隊主檔!$D$2:$D$31,MATCH($B11,球隊主檔!$A$2:$A$31,0)) -> 美聯 | E11: =INDEX(球隊主檔!$E$2:$E$31,MATCH($B11,球隊主檔!$A$2:$A$31,0)) -> 美中 | F11: 82 | G11: =INDEX(球季參數!$B$2:$B$4,MATCH($A11,球季參數!$A$2:$A$4,0))-F11 -> 80 | H11: =IF(F11+G11=0,0,F11/(F11+G11)) -> 0.50617284 | I11: =(SUMPRODUCT(MAX(($A$2:$A$91=$A11)*($E$2:$E$91=$E11)*$F$2:$F$91))-F11+G11-SUMPRODUCT(MIN(($A$2:$A$91=$A11)*($E$2:$E$91=$E11)*$G$2:$G$91+(1-($A$2:$A$91=$A11)*($E$2:$E$91=$E11))*999)))/2 -> 13 | J11: 752 | K11: 766 | L11: =J11-K11 -> -14 | M11: =IF(POWER(J11,INDEX(球季參數!$D$2:$D$4,MATCH($A11,球季參數!$A$2:$A$4,0)))+POWER(K11,INDEX(球季參數!$D$2:$D$4,MATCH($A11,球季參數!$A$2:$A$4,0)))=0,0,POWER(J11,INDEX(球季參數!$D$2:$D$4,MATCH($A11,球季參數!$A$2:$A$4,0)))/(POWER(J11,INDEX(球季參數!$D$2:$D$4,MATCH($A11,球季參數!$A$2:$A$4,0)))+POWER(K11,INDEX(球季參數!$D$2:$D$4,MATCH($A11,球季參數!$A$2:$A$4,0))))) -> 0.49156183 | N11: =M11*(F11+G11) -> 79.633016 | O11: =F11-N11 -> 2.3669841
A12: 2024 | B12: ATH | C12: =INDEX(球隊主檔!$C$2:$C$31,MATCH($B12,球隊主檔!$A$2:$A$31,0)) -> 運動家 | D12: =INDEX(球隊主檔!$D$2:$D$31,MATCH($B12,球隊主檔!$A$2:$A$31,0)) -> 美聯 | E12: =INDEX(球隊主檔!$E$2:$E$31,MATCH($B12,球隊主檔!$A$2:$A$31,0)) -> 美西 | F12: 79 | G12: =INDEX(球季參數!$B$2:$B$4,MATCH($A12,球季參數!$A$2:$A$4,0))-F12 -> 83 | H12: =IF(F12+G12=0,0,F12/(F12+G12)) -> 0.48765432 | I12: =(SUMPRODUCT(MAX(($A$2:$A$91=$A12)*($E$2:$E$91=$E12)*$F$2:$F$91))-F12+G12-SUMPRODUCT(MIN(($A$2:$A$91=$A12)*($E$2:$E$91=$E12)*$G$2:$G$91+(1-($A$2:$A$91=$A12)*($E$2:$E$91=$E12))*999)))/2 -> 20 | J12: 672 | K12: 702 | L12: =J12-K12 -> -30 | M12: =IF(POWER(J12,INDEX(球季參數!$D$2:$D$4,MATCH($A12,球季參數!$A$2:$A$4,0)))+POWER(K12,INDEX(球季參數!$D$2:$D$4,MATCH($A12,球季參數!$A$2:$A$4,0)))=0,0,POWER(J12,INDEX(球季參數!$D$2:$D$4,MATCH($A12,球季參數!$A$2:$A$4,0)))/(POWER(J12,INDEX(球季參數!$D$2:$D$4,MATCH($A12,球季參數!$A$2:$A$4,0)))+POWER(K12,INDEX(球季參數!$D$2:$D$4,MATCH($A12,球季參數!$A$2:$A$4,0))))) -> 0.48002929 | N12: =M12*(F12+G12) -> 77.764745 | O12: =F12-N12 -> 1.2352553
A13: 2024 | B13: HOU | C13: =INDEX(球隊主檔!$C$2:$C$31,MATCH($B13,球隊主檔!$A$2:$A$31,0)) -> 休士頓太空人 | D13: =INDEX(球隊主檔!$D$2:$D$31,MATCH($B13,球隊主檔!$A$2:$A$31,0)) -> 美聯 | E13: =INDEX(球隊主檔!$E$2:$E$31,MATCH($B13,球隊主檔!$A$2:$A$31,0)) -> 美西 | F13: 99 | G13: =INDEX(球季參數!$B$2:$B$4,MATCH($A13,球季參數!$A$2:$A$4,0))-F13 -> 63 | H13: =IF(F13+G13=0,0,F13/(F13+G13)) -> 0.61111111 | I13: =(SUMPRODUCT(MAX(($A$2:$A$91=$A13)*($E$2:$E$91=$E13)*$F$2:$F$91))-F13+G13-SUMPRODUCT(MIN(($A$2:$A$91=$A13)*($E$2:$E$91=$E13)*$G$2:$G$91+(1-($A$2:$A$91=$A13)*($E$2:$E$91=$E13))*999)))/2 -> 0 | J13: 763 | K13: 588 | L13: =J13-K13 -> 175 | M13: =IF(POWER(J13,INDEX(球季參數!$D$2:$D$4,MATCH($A13,球季參數!$A$2:$A$4,0)))+POWER(K13,INDEX(球季參數!$D$2:$D$4,MATCH($A13,球季參數!$A$2:$A$4,0)))=0,0,POWER(J13,INDEX(球季參數!$D$2:$D$4,MATCH($A13,球季參數!$A$2:$A$4,0)))/(POWER(J13,INDEX(球季參數!$D$2:$D$4,MATCH($A13,球季參數!$A$2:$A$4,0)))+POWER(K13,INDEX(球季參數!$D$2:$D$4,MATCH($A13,球季參數!$A$2:$A$4,0))))) -> 0.61698531 | N13: =M13*(F13+G13) -> 99.951621 | O13: =F13-N13 -> -0.95162065
... A91: 2026 | B91: SFG | C91: =INDEX(球隊主檔!$C$2:$C$31,MATCH($B91,球隊主檔!$A$2:$A$31,0)) -> 舊金山巨人 | D91: =INDEX(球隊主檔!$D$2:$D$31,MATCH($B91,球隊主檔!$A$2:$A$31,0)) -> 國聯 | E91: =INDEX(球隊主檔!$E$2:$E$31,MATCH($B91,球隊主檔!$A$2:$A$31,0)) -> 國西 | F91: 75 | G91: =INDEX(球季參數!$B$2:$B$4,MATCH($A91,球季參數!$A$2:$A$4,0))-F91 -> 87 | H91: =IF(F91+G91=0,0,F91/(F91+G91)) -> 0.46296296 | I91: =(SUMPRODUCT(MAX(($A$2:$A$91=$A91)*($E$2:$E$91=$E91)*$F$2:$F$91))-F91+G91-SUMPRODUCT(MIN(($A$2:$A$91=$A91)*($E$2:$E$91=$E91)*$G$2:$G$91+(1-($A$2:$A$91=$A91)*($E$2:$E$91=$E91))*999)))/2 -> 15 | J91: 616 | K91: 699 | L91: =J91-K91 -> -83 | M91: =IF(POWER(J91,INDEX(球季參數!$D$2:$D$4,MATCH($A91,球季參數!$A$2:$A$4,0)))+POWER(K91,INDEX(球季參數!$D$2:$D$4,MATCH($A91,球季參數!$A$2:$A$4,0)))=0,0,POWER(J91,INDEX(球季參數!$D$2:$D$4,MATCH($A91,球季參數!$A$2:$A$4,0)))/(POWER(J91,INDEX(球季參數!$D$2:$D$4,MATCH($A91,球季參數!$A$2:$A$4,0)))+POWER(K91,INDEX(球季參數!$D$2:$D$4,MATCH($A91,球季參數!$A$2:$A$4,0))))) -> 0.44242676 | N91: =M91*(F91+G91) -> 71.673136 | O91: =F91-N91 -> 3.3268643

Sheet 球隊球季彙總
A1: 球季 | B1: 球隊代號 | C1: 球隊中文名 | D1: 聯盟 | E1: 分區 | F1: 勝場 | G1: 勝率 | H1: 樣本打者數 | I1: 打席合計 | J1: 打數合計 | K1: 安打合計 | L1: 壘打數合計 | M1: 全壘打合計 | N1: 打點合計 | O1: 盜壘成功合計 | P1: 團隊打擊率 | Q1: 團隊長打率 | R1: 樣本投手數 | S1: 投球出局數合計 | T1: 投球局數合計 | U1: 三振合計 | V1: 自責分合計 | W1: 團隊防禦率 | X1: 團隊每九局三振
A2: 2024 | B2: BAL | C2: =INDEX(球隊主檔!$C$2:$C$31,MATCH($B2,球隊主檔!$A$2:$A$31,0)) -> 巴爾的摩金鶯 | D2: =INDEX(球隊主檔!$D$2:$D$31,MATCH($B2,球隊主檔!$A$2:$A$31,0)) -> 美聯 | E2: =INDEX(球隊主檔!$E$2:$E$31,MATCH($B2,球隊主檔!$A$2:$A$31,0)) -> 美東 | F2: =SUMIFS(球隊戰績!$F$2:$F$91,球隊戰績!$A$2:$A$91,$A2,球隊戰績!$B$2:$B$91,$B2) -> 83 | G2: =IF(INDEX(球季參數!$B$2:$B$4,MATCH($A2,球季參數!$A$2:$A$4,0))=0,0,F2/INDEX(球季參數!$B$2:$B$4,MATCH($A2,球季參數!$A$2:$A$4,0))) -> 0.51234568 | H2: =COUNTIFS(打擊成績!$A$2:$A$901,$A2,打擊成績!$D$2:$D$901,$B2) -> 10 | I2: =SUMIFS(打擊成績!$J$2:$J$901,打擊成績!$A$2:$A$901,$A2,打擊成績!$D$2:$D$901,$B2) -> 4882 | J2: =SUMIFS(打擊成績!$K$2:$K$901,打擊成績!$A$2:$A$901,$A2,打擊成績!$D$2:$D$901,$B2) -> 4352 | K2: =SUMIFS(打擊成績!$M$2:$M$901,打擊成績!$A$2:$A$901,$A2,打擊成績!$D$2:$D$901,$B2) -> 1064 | L2: =SUMIFS(打擊成績!$X$2:$X$901,打擊成績!$A$2:$A$901,$A2,打擊成績!$D$2:$D$901,$B2) -> 1981 | M2: =SUMIFS(打擊成績!$P$2:$P$901,打擊成績!$A$2:$A$901,$A2,打擊成績!$D$2:$D$901,$B2) -> 195 | N2: =SUMIFS(打擊成績!$Q$2:$Q$901,打擊成績!$A$2:$A$901,$A2,打擊成績!$D$2:$D$901,$B2) -> 673 | O2: =SUMIFS(打擊成績!$V$2:$V$901,打擊成績!$A$2:$A$901,$A2,打擊成績!$D$2:$D$901,$B2) -> 106 | P2: =IF(J2=0,0,K2/J2) -> 0.24448529 | Q2: =IF(J2=0,0,L2/J2) -> 0.45519301 | R2: =COUNTIFS(投手成績!$A$2:$A$901,$A2,投手成績!$D$2:$D$901,$B2) -> 10 | S2: =SUMIFS(投手成績!$O$2:$O$901,投手成績!$A$2:$A$901,$A2,投手成績!$D$2:$D$901,$B2) -> 2768 | T2: =S2/3 -> 922.66667 | U2: =SUMIFS(投手成績!$W$2:$W$901,投手成績!$A$2:$A$901,$A2,投手成績!$D$2:$D$901,$B2) -> 884 | V2: =SUMIFS(投手成績!$T$2:$T$901,投手成績!$A$2:$A$901,$A2,投手成績!$D$2:$D$901,$B2) -> 409 | W2: =IF(S2=0,0,V2*27/S2) -> 3.9895231 | X2: =IF(S2=0,0,U2*27/S2) -> 8.6228324
A3: 2024 | B3: BOS | C3: =INDEX(球隊主檔!$C$2:$C$31,MATCH($B3,球隊主檔!$A$2:$A$31,0)) -> 波士頓紅襪 | D3: =INDEX(球隊主檔!$D$2:$D$31,MATCH($B3,球隊主檔!$A$2:$A$31,0)) -> 美聯 | E3: =INDEX(球隊主檔!$E$2:$E$31,MATCH($B3,球隊主檔!$A$2:$A$31,0)) -> 美東 | F3: =SUMIFS(球隊戰績!$F$2:$F$91,球隊戰績!$A$2:$A$91,$A3,球隊戰績!$B$2:$B$91,$B3) -> 88 | G3: =IF(INDEX(球季參數!$B$2:$B$4,MATCH($A3,球季參數!$A$2:$A$4,0))=0,0,F3/INDEX(球季參數!$B$2:$B$4,MATCH($A3,球季參數!$A$2:$A$4,0))) -> 0.54320988 | H3: =COUNTIFS(打擊成績!$A$2:$A$901,$A3,打擊成績!$D$2:$D$901,$B3) -> 10 | I3: =SUMIFS(打擊成績!$J$2:$J$901,打擊成績!$A$2:$A$901,$A3,打擊成績!$D$2:$D$901,$B3) -> 4511 | J3: =SUMIFS(打擊成績!$K$2:$K$901,打擊成績!$A$2:$A$901,$A3,打擊成績!$D$2:$D$901,$B3) -> 4067 | K3: =SUMIFS(打擊成績!$M$2:$M$901,打擊成績!$A$2:$A$901,$A3,打擊成績!$D$2:$D$901,$B3) -> 992 | L3: =SUMIFS(打擊成績!$X$2:$X$901,打擊成績!$A$2:$A$901,$A3,打擊成績!$D$2:$D$901,$B3) -> 1949 | M3: =SUMIFS(打擊成績!$P$2:$P$901,打擊成績!$A$2:$A$901,$A3,打擊成績!$D$2:$D$901,$B3) -> 193 | N3: =SUMIFS(打擊成績!$Q$2:$Q$901,打擊成績!$A$2:$A$901,$A3,打擊成績!$D$2:$D$901,$B3) -> 634 | O3: =SUMIFS(打擊成績!$V$2:$V$901,打擊成績!$A$2:$A$901,$A3,打擊成績!$D$2:$D$901,$B3) -> 157 | P3: =IF(J3=0,0,K3/J3) -> 0.24391443 | Q3: =IF(J3=0,0,L3/J3) -> 0.47922301 | R3: =COUNTIFS(投手成績!$A$2:$A$901,$A3,投手成績!$D$2:$D$901,$B3) -> 10 | S3: =SUMIFS(投手成績!$O$2:$O$901,投手成績!$A$2:$A$901,$A3,投手成績!$D$2:$D$901,$B3) -> 2894 | T3: =S3/3 -> 964.66667 | U3: =SUMIFS(投手成績!$W$2:$W$901,投手成績!$A$2:$A$901,$A3,投手成績!$D$2:$D$901,$B3) -> 988 | V3: =SUMIFS(投手成績!$T$2:$T$901,投手成績!$A$2:$A$901,$A3,投手成績!$D$2:$D$901,$B3) -> 403 | W3: =IF(S3=0,0,V3*27/S3) -> 3.759848 | X3: =IF(S3=0,0,U3*27/S3) -> 9.2176918
A4: 2024 | B4: NYY | C4: =INDEX(球隊主檔!$C$2:$C$31,MATCH($B4,球隊主檔!$A$2:$A$31,0)) -> 紐約洋基 | D4: =INDEX(球隊主檔!$D$2:$D$31,MATCH($B4,球隊主檔!$A$2:$A$31,0)) -> 美聯 | E4: =INDEX(球隊主檔!$E$2:$E$31,MATCH($B4,球隊主檔!$A$2:$A$31,0)) -> 美東 | F4: =SUMIFS(球隊戰績!$F$2:$F$91,球隊戰績!$A$2:$A$91,$A4,球隊戰績!$B$2:$B$91,$B4) -> 87 | G4: =IF(INDEX(球季參數!$B$2:$B$4,MATCH($A4,球季參數!$A$2:$A$4,0))=0,0,F4/INDEX(球季參數!$B$2:$B$4,MATCH($A4,球季參數!$A$2:$A$4,0))) -> 0.53703704 | H4: =COUNTIFS(打擊成績!$A$2:$A$901,$A4,打擊成績!$D$2:$D$901,$B4) -> 10 | I4: =SUMIFS(打擊成績!$J$2:$J$901,打擊成績!$A$2:$A$901,$A4,打擊成績!$D$2:$D$901,$B4) -> 4574 | J4: =SUMIFS(打擊成績!$K$2:$K$901,打擊成績!$A$2:$A$901,$A4,打擊成績!$D$2:$D$901,$B4) -> 4132 | K4: =SUMIFS(打擊成績!$M$2:$M$901,打擊成績!$A$2:$A$901,$A4,打擊成績!$D$2:$D$901,$B4) -> 1086 | L4: =SUMIFS(打擊成績!$X$2:$X$901,打擊成績!$A$2:$A$901,$A4,打擊成績!$D$2:$D$901,$B4) -> 1941 | M4: =SUMIFS(打擊成績!$P$2:$P$901,打擊成績!$A$2:$A$901,$A4,打擊成績!$D$2:$D$901,$B4) -> 185 | N4: =SUMIFS(打擊成績!$Q$2:$Q$901,打擊成績!$A$2:$A$901,$A4,打擊成績!$D$2:$D$901,$B4) -> 661 | O4: =SUMIFS(打擊成績!$V$2:$V$901,打擊成績!$A$2:$A$901,$A4,打擊成績!$D$2:$D$901,$B4) -> 67 | P4: =IF(J4=0,0,K4/J4) -> 0.26282672 | Q4: =IF(J4=0,0,L4/J4) -> 0.46974831 | R4: =COUNTIFS(投手成績!$A$2:$A$901,$A4,投手成績!$D$2:$D$901,$B4) -> 10 | S4: =SUMIFS(投手成績!$O$2:$O$901,投手成績!$A$2:$A$901,$A4,投手成績!$D$2:$D$901,$B4) -> 2966 | T4: =S4/3 -> 988.66667 | U4: =SUMIFS(投手成績!$W$2:$W$901,投手成績!$A$2:$A$901,$A4,投手成績!$D$2:$D$901,$B4) -> 943 | V4: =SUMIFS(投手成績!$T$2:$T$901,投手成績!$A$2:$A$901,$A4,投手成績!$D$2:$D$901,$B4) -> 394 | W4: =IF(S4=0,0,V4*27/S4) -> 3.5866487 | X4: =IF(S4=0,0,U4*27/S4) -> 8.5842886
A5: 2024 | B5: TBR | C5: =INDEX(球隊主檔!$C$2:$C$31,MATCH($B5,球隊主檔!$A$2:$A$31,0)) -> 坦帕灣光芒 | D5: =INDEX(球隊主檔!$D$2:$D$31,MATCH($B5,球隊主檔!$A$2:$A$31,0)) -> 美聯 | E5: =INDEX(球隊主檔!$E$2:$E$31,MATCH($B5,球隊主檔!$A$2:$A$31,0)) -> 美東 | F5: =SUMIFS(球隊戰績!$F$2:$F$91,球隊戰績!$A$2:$A$91,$A5,球隊戰績!$B$2:$B$91,$B5) -> 75 | G5: =IF(INDEX(球季參數!$B$2:$B$4,MATCH($A5,球季參數!$A$2:$A$4,0))=0,0,F5/INDEX(球季參數!$B$2:$B$4,MATCH($A5,球季參數!$A$2:$A$4,0))) -> 0.46296296 | H5: =COUNTIFS(打擊成績!$A$2:$A$901,$A5,打擊成績!$D$2:$D$901,$B5) -> 10 | I5: =SUMIFS(打擊成績!$J$2:$J$901,打擊成績!$A$2:$A$901,$A5,打擊成績!$D$2:$D$901,$B5) -> 4606 | J5: =SUMIFS(打擊成績!$K$2:$K$901,打擊成績!$A$2:$A$901,$A5,打擊成績!$D$2:$D$901,$B5) -> 4193 | K5: =SUMIFS(打擊成績!$M$2:$M$901,打擊成績!$A$2:$A$901,$A5,打擊成績!$D$2:$D$901,$B5) -> 981 | L5: =SUMIFS(打擊成績!$X$2:$X$901,打擊成績!$A$2:$A$901,$A5,打擊成績!$D$2:$D$901,$B5) -> 1728 | M5: =SUMIFS(打擊成績!$P$2:$P$901,打擊成績!$A$2:$A$901,$A5,打擊成績!$D$2:$D$901,$B5) -> 126 | N5: =SUMIFS(打擊成績!$Q$2:$Q$901,打擊成績!$A$2:$A$901,$A5,打擊成績!$D$2:$D$901,$B5) -> 487 | O5: =SUMIFS(打擊成績!$V$2:$V$901,打擊成績!$A$2:$A$901,$A5,打擊成績!$D$2:$D$901,$B5) -> 167 | P5: =IF(J5=0,0,K5/J5) -> 0.23396136 | Q5: =IF(J5=0,0,L5/J5) -> 0.41211543 | R5: =COUNTIFS(投手成績!$A$2:$A$901,$A5,投手成績!$D$2:$D$901,$B5) -> 10 | S5: =SUMIFS(投手成績!$O$2:$O$901,投手成績!$A$2:$A$901,$A5,投手成績!$D$2:$D$901,$B5) -> 3163 | T5: =S5/3 -> 1054.3333 | U5: =SUMIFS(投手成績!$W$2:$W$901,投手成績!$A$2:$A$901,$A5,投手成績!$D$2:$D$901,$B5) -> 1059 | V5: =SUMIFS(投手成績!$T$2:$T$901,投手成績!$A$2:$A$901,$A5,投手成績!$D$2:$D$901,$B5) -> 506 | W5: =IF(S5=0,0,V5*27/S5) -> 4.3193171 | X5: =IF(S5=0,0,U5*27/S5) -> 9.0398356
A6: 2024 | B6: TOR | C6: =INDEX(球隊主檔!$C$2:$C$31,MATCH($B6,球隊主檔!$A$2:$A$31,0)) -> 多倫多藍鳥 | D6: =INDEX(球隊主檔!$D$2:$D$31,MATCH($B6,球隊主檔!$A$2:$A$31,0)) -> 美聯 | E6: =INDEX(球隊主檔!$E$2:$E$31,MATCH($B6,球隊主檔!$A$2:$A$31,0)) -> 美東 | F6: =SUMIFS(球隊戰績!$F$2:$F$91,球隊戰績!$A$2:$A$91,$A6,球隊戰績!$B$2:$B$91,$B6) -> 73 | G6: =IF(INDEX(球季參數!$B$2:$B$4,MATCH($A6,球季參數!$A$2:$A$4,0))=0,0,F6/INDEX(球季參數!$B$2:$B$4,MATCH($A6,球季參數!$A$2:$A$4,0))) -> 0.45061728 | H6: =COUNTIFS(打擊成績!$A$2:$A$901,$A6,打擊成績!$D$2:$D$901,$B6) -> 10 | I6: =SUMIFS(打擊成績!$J$2:$J$901,打擊成績!$A$2:$A$901,$A6,打擊成績!$D$2:$D$901,$B6) -> 4842 | J6: =SUMIFS(打擊成績!$K$2:$K$901,打擊成績!$A$2:$A$901,$A6,打擊成績!$D$2:$D$901,$B6) -> 4303 | K6: =SUMIFS(打擊成績!$M$2:$M$901,打擊成績!$A$2:$A$901,$A6,打擊成績!$D$2:$D$901,$B6) -> 1078 | L6: =SUMIFS(打擊成績!$X$2:$X$901,打擊成績!$A$2:$A$901,$A6,打擊成績!$D$2:$D$901,$B6) -> 1939 | M6: =SUMIFS(打擊成績!$P$2:$P$901,打擊成績!$A$2:$A$901,$A6,打擊成績!$D$2:$D$901,$B6) -> 170 | N6: =SUMIFS(打擊成績!$Q$2:$Q$901,打擊成績!$A$2:$A$901,$A6,打擊成績!$D$2:$D$901,$B6) -> 595 | O6: =SUMIFS(打擊成績!$V$2:$V$901,打擊成績!$A$2:$A$901,$A6,打擊成績!$D$2:$D$901,$B6) -> 130 | P6: =IF(J6=0,0,K6/J6) -> 0.25052289 | Q6: =IF(J6=0,0,L6/J6) -> 0.45061585 | R6: =COUNTIFS(投手成績!$A$2:$A$901,$A6,投手成績!$D$2:$D$901,$B6) -> 10 | S6: =SUMIFS(投手成績!$O$2:$O$901,投手成績!$A$2:$A$901,$A6,投手成績!$D$2:$D$901,$B6) -> 2826 | T6: =S6/3 -> 942 | U6: =SUMIFS(投手成績!$W$2:$W$901,投手成績!$A$2:$A$901,$A6,投手成績!$D$2:$D$901,$B6) -> 1061 | V6: =SUMIFS(投手成績!$T$2:$T$901,投手成績!$A$2:$A$901,$A6,投手成績!$D$2:$D$901,$B6) -> 430 | W6: =IF(S6=0,0,V6*27/S6) -> 4.1082803 | X6: =IF(S6=0,0,U6*27/S6) -> 10.136943
A7: 2024 | B7: CWS | C7: =INDEX(球隊主檔!$C$2:$C$31,MATCH($B7,球隊主檔!$A$2:$A$31,0)) -> 芝加哥白襪 | D7: =INDEX(球隊主檔!$D$2:$D$31,MATCH($B7,球隊主檔!$A$2:$A$31,0)) -> 美聯 | E7: =INDEX(球隊主檔!$E$2:$E$31,MATCH($B7,球隊主檔!$A$2:$A$31,0)) -> 美中 | F7: =SUMIFS(球隊戰績!$F$2:$F$91,球隊戰績!$A$2:$A$91,$A7,球隊戰績!$B$2:$B$91,$B7) -> 86 | G7: =IF(INDEX(球季參數!$B$2:$B$4,MATCH($A7,球季參數!$A$2:$A$4,0))=0,0,F7/INDEX(球季參數!$B$2:$B$4,MATCH($A7,球季參數!$A$2:$A$4,0))) -> 0.5308642 | H7: =COUNTIFS(打擊成績!$A$2:$A$901,$A7,打擊成績!$D$2:$D$901,$B7) -> 10 | I7: =SUMIFS(打擊成績!$J$2:$J$901,打擊成績!$A$2:$A$901,$A7,打擊成績!$D$2:$D$901,$B7) -> 5072 | J7: =SUMIFS(打擊成績!$K$2:$K$901,打擊成績!$A$2:$A$901,$A7,打擊成績!$D$2:$D$901,$B7) -> 4587 | K7: =SUMIFS(打擊成績!$M$2:$M$901,打擊成績!$A$2:$A$901,$A7,打擊成績!$D$2:$D$901,$B7) -> 1109 | L7: =SUMIFS(打擊成績!$X$2:$X$901,打擊成績!$A$2:$A$901,$A7,打擊成績!$D$2:$D$901,$B7) -> 1858 | M7: =SUMIFS(打擊成績!$P$2:$P$901,打擊成績!$A$2:$A$901,$A7,打擊成績!$D$2:$D$901,$B7) -> 142 | N7: =SUMIFS(打擊成績!$Q$2:$Q$901,打擊成績!$A$2:$A$901,$A7,打擊成績!$D$2:$D$901,$B7) -> 531 | O7: =SUMIFS(打擊成績!$V$2:$V$901,打擊成績!$A$2:$A$901,$A7,打擊成績!$D$2:$D$901,$B7) -> 83 | P7: =IF(J7=0,0,K7/J7) -> 0.24177022 | Q7: =IF(J7=0,0,L7/J7) -> 0.40505777 | R7: =COUNTIFS(投手成績!$A$2:$A$901,$A7,投手成績!$D$2:$D$901,$B7) -> 10 | S7: =SUMIFS(投手成績!$O$2:$O$901,投手成績!$A$2:$A$901,$A7,投手成績!$D$2:$D$901,$B7) -> 3408 | T7: =S7/3 -> 1136 | U7: =SUMIFS(投手成績!$W$2:$W$901,投手成績!$A$2:$A$901,$A7,投手成績!$D$2:$D$901,$B7) -> 1142 | V7: =SUMIFS(投手成績!$T$2:$T$901,投手成績!$A$2:$A$901,$A7,投手成績!$D$2:$D$901,$B7) -> 551 | W7: =IF(S7=0,0,V7*27/S7) -> 4.3653169 | X7: =IF(S7=0,0,U7*27/S7) -> 9.0475352
A8: 2024 | B8: CLE | C8: =INDEX(球隊主檔!$C$2:$C$31,MATCH($B8,球隊主檔!$A$2:$A$31,0)) -> 克里夫蘭守護者 | D8: =INDEX(球隊主檔!$D$2:$D$31,MATCH($B8,球隊主檔!$A$2:$A$31,0)) -> 美聯 | E8: =INDEX(球隊主檔!$E$2:$E$31,MATCH($B8,球隊主檔!$A$2:$A$31,0)) -> 美中 | F8: =SUMIFS(球隊戰績!$F$2:$F$91,球隊戰績!$A$2:$A$91,$A8,球隊戰績!$B$2:$B$91,$B8) -> 80 | G8: =IF(INDEX(球季參數!$B$2:$B$4,MATCH($A8,球季參數!$A$2:$A$4,0))=0,0,F8/INDEX(球季參數!$B$2:$B$4,MATCH($A8,球季參數!$A$2:$A$4,0))) -> 0.49382716 | H8: =COUNTIFS(打擊成績!$A$2:$A$901,$A8,打擊成績!$D$2:$D$901,$B8) -> 10 | I8: =SUMIFS(打擊成績!$J$2:$J$901,打擊成績!$A$2:$A$901,$A8,打擊成績!$D$2:$D$901,$B8) -> 4995 | J8: =SUMIFS(打擊成績!$K$2:$K$901,打擊成績!$A$2:$A$901,$A8,打擊成績!$D$2:$D$901,$B8) -> 4544 | K8: =SUMIFS(打擊成績!$M$2:$M$901,打擊成績!$A$2:$A$901,$A8,打擊成績!$D$2:$D$901,$B8) -> 1111 | L8: =SUMIFS(打擊成績!$X$2:$X$901,打擊成績!$A$2:$A$901,$A8,打擊成績!$D$2:$D$901,$B8) -> 1961 | M8: =SUMIFS(打擊成績!$P$2:$P$901,打擊成績!$A$2:$A$901,$A8,打擊成績!$D$2:$D$901,$B8) -> 165 | N8: =SUMIFS(打擊成績!$Q$2:$Q$901,打擊成績!$A$2:$A$901,$A8,打擊成績!$D$2:$D$901,$B8) -> 606 | O8: =SUMIFS(打擊成績!$V$2:$V$901,打擊成績!$A$2:$A$901,$A8,打擊成績!$D$2:$D$901,$B8) -> 137 | P8: =IF(J8=0,0,K8/J8) -> 0.24449824 | Q8: =IF(J8=0,0,L8/J8) -> 0.4315581 | R8: =COUNTIFS(投手成績!$A$2:$A$901,$A8,投手成績!$D$2:$D$901,$B8) -> 10 | S8: =SUMIFS(投手成績!$O$2:$O$901,投手成績!$A$2:$A$901,$A8,投手成績!$D$2:$D$901,$B8) -> 2778 | T8: =S8/3 -> 926 | U8: =SUMIFS(投手成績!$W$2:$W$901,投手成績!$A$2:$A$901,$A8,投手成績!$D$2:$D$901,$B8) -> 945 | V8: =SUMIFS(投手成績!$T$2:$T$901,投手成績!$A$2:$A$901,$A8,投手成績!$D$2:$D$901,$B8) -> 418 | W8: =IF(S8=0,0,V8*27/S8) -> 4.062635 | X8: =IF(S8=0,0,U8*27/S8) -> 9.1846652
A9: 2024 | B9: DET | C9: =INDEX(球隊主檔!$C$2:$C$31,MATCH($B9,球隊主檔!$A$2:$A$31,0)) -> 底特律老虎 | D9: =INDEX(球隊主檔!$D$2:$D$31,MATCH($B9,球隊主檔!$A$2:$A$31,0)) -> 美聯 | E9: =INDEX(球隊主檔!$E$2:$E$31,MATCH($B9,球隊主檔!$A$2:$A$31,0)) -> 美中 | F9: =SUMIFS(球隊戰績!$F$2:$F$91,球隊戰績!$A$2:$A$91,$A9,球隊戰績!$B$2:$B$91,$B9) -> 95 | G9: =IF(INDEX(球季參數!$B$2:$B$4,MATCH($A9,球季參數!$A$2:$A$4,0))=0,0,F9/INDEX(球季參數!$B$2:$B$4,MATCH($A9,球季參數!$A$2:$A$4,0))) -> 0.58641975 | H9: =COUNTIFS(打擊成績!$A$2:$A$901,$A9,打擊成績!$D$2:$D$901,$B9) -> 10 | I9: =SUMIFS(打擊成績!$J$2:$J$901,打擊成績!$A$2:$A$901,$A9,打擊成績!$D$2:$D$901,$B9) -> 5170 | J9: =SUMIFS(打擊成績!$K$2:$K$901,打擊成績!$A$2:$A$901,$A9,打擊成績!$D$2:$D$901,$B9) -> 4664 | K9: =SUMIFS(打擊成績!$M$2:$M$901,打擊成績!$A$2:$A$901,$A9,打擊成績!$D$2:$D$901,$B9) -> 1183 | L9: =SUMIFS(打擊成績!$X$2:$X$901,打擊成績!$A$2:$A$901,$A9,打擊成績!$D$2:$D$901,$B9) -> 2077 | M9: =SUMIFS(打擊成績!$P$2:$P$901,打擊成績!$A$2:$A$901,$A9,打擊成績!$D$2:$D$901,$B9) -> 188 | N9: =SUMIFS(打擊成績!$Q$2:$Q$901,打擊成績!$A$2:$A$901,$A9,打擊成績!$D$2:$D$901,$B9) -> 677 | O9: =SUMIFS(打擊成績!$V$2:$V$901,打擊成績!$A$2:$A$901,$A9,打擊成績!$D$2:$D$901,$B9) -> 152 | P9: =IF(J9=0,0,K9/J9) -> 0.25364494 | Q9: =IF(J9=0,0,L9/J9) -> 0.4453259 | R9: =COUNTIFS(投手成績!$A$2:$A$901,$A9,投手成績!$D$2:$D$901,$B9) -> 10 | S9: =SUMIFS(投手成績!$O$2:$O$901,投手成績!$A$2:$A$901,$A9,投手成績!$D$2:$D$901,$B9) -> 2978 | T9: =S9/3 -> 992.66667 | U9: =SUMIFS(投手成績!$W$2:$W$901,投手成績!$A$2:$A$901,$A9,投手成績!$D$2:$D$901,$B9) -> 993 | V9: =SUMIFS(投手成績!$T$2:$T$901,投手成績!$A$2:$A$901,$A9,投手成績!$D$2:$D$901,$B9) -> 527 | W9: =IF(S9=0,0,V9*27/S9) -> 4.778039 | X9: =IF(S9=0,0,U9*27/S9) -> 9.0030222
