Workbook

Sheet 使用說明
A1: 類別 | B1: 說明
A2: 結構規範 | B2: 每張資料工作表第 1 列為欄位標題，第 2 列起為資料，中間無空列、無小計或合計列。
A3: 結構規範 | B3: 全檔無合併儲存格、無跨欄置中、無標題橫幅，可直接以 pandas.read_excel(header=0) 讀取。
A4: 結構規範 | B4: 每張資料工作表皆已定義為 Excel 表格物件，名稱為 tbl_ 開頭，可供 BI 工具直接指定資料來源。
A5: 結構規範 | B5: 合計與比率不放在資料表內，統一放在「年度關鍵指標」工作表，以指標代碼/數值的長格式呈現。
A6: 主鍵 | B6: 「月營運明細」主鍵為 年月 + 門市代號，兩者組合唯一，共 96 筆。
A7: 主鍵 | B7: 「門市主檔」主鍵為 門市代號；「月曆參數」主鍵為 年月。其餘工作表皆以此二者外連。
A8: 資料型別 | B8: 年月一律為文字 YYYY-MM；月為 1-12 純整數；日期一律 yyyy-mm-dd。
A9: 資料型別 | B9: 所有百分比欄位以小數儲存（0.227 代表 22.7%），僅顯示格式為百分比。
A10: 資料型別 | B10: 金額單位一律為新台幣元，未四捨五入至千元；欄位標題不含單位，單位請查「欄位定義」。
A11: 顏色規則 | B11: 藍色字＝手動輸入的原始資料；黑色字＝同表公式；綠色字＝跨工作表連結。
A12: 維護方式 | B12: 新增門市：先在「門市主檔」加一列，再到「月營運明細」補該店 12 個月資料。
... A20: 圖表 | B20: 「圖表預覽」工作表僅供人工檢視，不含任何原始資料，自動化流程可略過該表。

Sheet 欄位定義
A1: 工作表 | B1: 欄位位置 | C1: 欄位代碼 | D1: 中文欄名 | E1: 資料型別 | F1: 單位 | G1: 資料來源
A2: 門市主檔 | B2: A | C2: store_id | D2: 門市代號 | E2: 文字 | G2: 手動輸入
A3: 門市主檔 | B3: B | C3: store_name | D3: 門市名稱 | E3: 文字 | G3: 手動輸入
A4: 門市主檔 | B4: C | C4: region | D4: 區域 | E4: 文字 | G4: 手動輸入
A5: 門市主檔 | B5: D | C5: city | D5: 縣市 | E5: 文字 | G5: 手動輸入
A6: 門市主檔 | B6: E | C6: open_date | D6: 開幕日 | E6: 日期 | G6: 手動輸入
A7: 門市主檔 | B7: F | C7: seats | D7: 座位數 | E7: 整數 | F7: 個 | G7: 手動輸入
A8: 門市主檔 | B8: G | C8: rent | D8: 月租金 | E8: 數值 | F8: NT$ | G8: 手動輸入
A9: 月曆參數 | B9: A | C9: period | D9: 年月 | E9: 文字 | F9: YYYY-MM | G9: 公式
A10: 月曆參數 | B10: B | C10: year | D10: 年 | E10: 整數 | G10: 手動輸入
A11: 月曆參數 | B11: C | C11: month | D11: 月 | E11: 整數 | F11: 1-12 | G11: 手動輸入
A12: 月曆參數 | B12: D | C12: month_start | D12: 月初日期 | E12: 日期 | G12: 公式
A13: 月曆參數 | B13: E | C13: days | D13: 當月天數 | E13: 整數 | F13: 天 | G13: 公式
A14: 月營運明細 | B14: A | C14: period | D14: 年月 | E14: 文字 | F14: YYYY-MM | G14: 公式
A15: 月營運明細 | B15: B | C15: year | D15: 年 | E15: 整數 | G15: 手動輸入
A16: 月營運明細 | B16: C | C16: month | D16: 月 | E16: 整數 | F16: 1-12 | G16: 手動輸入
A17: 月營運明細 | B17: D | C17: store_id | D17: 門市代號 | E17: 文字 | G17: 手動輸入
A18: 月營運明細 | B18: E | C18: store_name | D18: 門市名稱 | E18: 文字 | G18: 連結 門市主檔
A19: 月營運明細 | B19: F | C19: region | D19: 區域 | E19: 文字 | G19: 連結 門市主檔
A20: 月營運明細 | B20: G | C20: revenue | D20: 營業額 | E20: 數值 | F20: NT$ | G20: 手動輸入
A21: 月營運明細 | B21: H | C21: cost_food | D21: 食材成本 | E21: 數值 | F21: NT$ | G21: 手動輸入
A22: 月營運明細 | B22: I | C22: cost_labor | D22: 人事成本 | E22: 數值 | F22: NT$ | G22: 手動輸入
A23: 月營運明細 | B23: J | C23: cost_rent | D23: 租金 | E23: 數值 | F23: NT$ | G23: 連結 門市主檔
A24: 月營運明細 | B24: K | C24: cost_utility | D24: 水電及雜支 | E24: 數值 | F24: NT$ | G24: 手動輸入
A25: 月營運明細 | B25: L | C25: cost_mkt | D25: 行銷費用 | E25: 數值 | F25: NT$ | G25: 手動輸入
A26: 月營運明細 | B26: M | C26: cost_total | D26: 總成本 | E26: 數值 | F26: NT$ | G26: 公式
A27: 月營運明細 | B27: N | C27: op_profit | D27: 營業利益 | E27: 數值 | F27: NT$ | G27: 公式
A28: 月營運明細 | B28: O | C28: op_margin | D28: 營業利益率 | E28: 百分比 | F28: 小數 | G28: 公式
A29: 月營運明細 | B29: P | C29: guests | D29: 來客數 | E29: 整數 | F29: 人次 | G29: 手動輸入
A30: 月營運明細 | B30: Q | C30: guests_daily | D30: 日均來客數 | E30: 數值 | F30: 人次/日 | G30: 公式
A31: 月營運明細 | B31: R | C31: avg_ticket | D31: 平均客單價 | E31: 數值 | F31: NT$ | G31: 公式
A32: 月營運明細 | B32: S | C32: top_item | D32: 當月人氣餐點 | E32: 文字 | G32: 手動輸入
A33: 月營運明細 | B33: T | C33: top_item_qty | D33: 人氣餐點份數 | E33: 整數 | F33: 份 | G33: 手動輸入
A34: 門市年度彙總 | B34: A | C34: store_id | D34: 門市代號 | E34: 文字 | G34: 手動輸入
A35: 門市年度彙總 | B35: B | C35: store_name | D35: 門市名稱 | E35: 文字 | G35: 連結 門市主檔
A36: 門市年度彙總 | B36: C | C36: region | D36: 區域 | E36: 文字 | G36: 連結 門市主檔
A37: 門市年度彙總 | B37: D | C37: revenue_y | D37: 年營業額 | E37: 數值 | F37: NT$ | G37: 公式
A38: 門市年度彙總 | B38: E | C38: cost_y | D38: 年總成本 | E38: 數值 | F38: NT$ | G38: 公式
A39: 門市年度彙總 | B39: F | C39: profit_y | D39: 年營業利益 | E39: 數值 | F39: NT$ | G39: 公式
A40: 門市年度彙總 | B40: G | C40: margin_y | D40: 營業利益率 | E40: 百分比 | F40: 小數 | G40: 公式
...

Sheet 門市主檔
A1: 門市代號 | B1: 門市名稱 | C1: 區域 | D1: 縣市 | E1: 開幕日 | F1: 座位數 | G1: 月租金
A2: TP01 | B2: 台北信義旗艦店 | C2: 北區 | D2: 台北市 | E2: 2019-03-15 | F2: 120 | G2: 480000
A3: TP02 | B3: 台北中山店 | C3: 北區 | D3: 台北市 | E3: 2020-07-01 | F3: 80 | G3: 320000
A4: NT01 | B4: 新北板橋店 | C4: 北區 | D4: 新北市 | E4: 2021-05-20 | F4: 95 | G4: 260000
A5: TY01 | B5: 桃園中壢店 | C5: 北區 | D5: 桃園市 | E5: 2022-09-10 | F5: 85 | G5: 190000
A6: TC01 | B6: 台中逢甲店 | C6: 中區 | D6: 台中市 | E6: 2020-11-08 | F6: 100 | G6: 230000
A7: TC02 | B7: 台中七期店 | C7: 中區 | D7: 台中市 | E7: 2023-04-22 | F7: 90 | G7: 285000
A8: TN01 | B8: 台南中西店 | C8: 南區 | D8: 台南市 | E8: 2021-12-03 | F8: 75 | G8: 165000
A9: KH01 | B9: 高雄左營店 | C9: 南區 | D9: 高雄市 | E9: 2022-02-18 | F9: 110 | G9: 210000

Sheet 月曆參數
A1: 年月 | B1: 年 | C1: 月 | D1: 月初日期 | E1: 當月天數
A2: =TEXT(B2,"0")&"-"&TEXT(C2,"00") -> 2025-01 | B2: 2025 | C2: 1 | D2: =DATE(B2,C2,1) -> 45658 | E2: =DAY(EOMONTH(D2,0)) -> 31
A3: =TEXT(B3,"0")&"-"&TEXT(C3,"00") -> 2025-02 | B3: 2025 | C3: 2 | D3: =DATE(B3,C3,1) -> 45689 | E3: =DAY(EOMONTH(D3,0)) -> 28
A4: =TEXT(B4,"0")&"-"&TEXT(C4,"00") -> 2025-03 | B4: 2025 | C4: 3 | D4: =DATE(B4,C4,1) -> 45717 | E4: =DAY(EOMONTH(D4,0)) -> 31
A5: =TEXT(B5,"0")&"-"&TEXT(C5,"00") -> 2025-04 | B5: 2025 | C5: 4 | D5: =DATE(B5,C5,1) -> 45748 | E5: =DAY(EOMONTH(D5,0)) -> 30
A6: =TEXT(B6,"0")&"-"&TEXT(C6,"00") -> 2025-05 | B6: 2025 | C6: 5 | D6: =DATE(B6,C6,1) -> 45778 | E6: =DAY(EOMONTH(D6,0)) -> 31
A7: =TEXT(B7,"0")&"-"&TEXT(C7,"00") -> 2025-06 | B7: 2025 | C7: 6 | D7: =DATE(B7,C7,1) -> 45809 | E7: =DAY(EOMONTH(D7,0)) -> 30
A8: =TEXT(B8,"0")&"-"&TEXT(C8,"00") -> 2025-07 | B8: 2025 | C8: 7 | D8: =DATE(B8,C8,1) -> 45839 | E8: =DAY(EOMONTH(D8,0)) -> 31
A9: =TEXT(B9,"0")&"-"&TEXT(C9,"00") -> 2025-08 | B9: 2025 | C9: 8 | D9: =DATE(B9,C9,1) -> 45870 | E9: =DAY(EOMONTH(D9,0)) -> 31
A10: =TEXT(B10,"0")&"-"&TEXT(C10,"00") -> 2025-09 | B10: 2025 | C10: 9 | D10: =DATE(B10,C10,1) -> 45901 | E10: =DAY(EOMONTH(D10,0)) -> 30
A11: =TEXT(B11,"0")&"-"&TEXT(C11,"00") -> 2025-10 | B11: 2025 | C11: 10 | D11: =DATE(B11,C11,1) -> 45931 | E11: =DAY(EOMONTH(D11,0)) -> 31
A12: =TEXT(B12,"0")&"-"&TEXT(C12,"00") -> 2025-11 | B12: 2025 | C12: 11 | D12: =DATE(B12,C12,1) -> 45962 | E12: =DAY(EOMONTH(D12,0)) -> 30
A13: =TEXT(B13,"0")&"-"&TEXT(C13,"00") -> 2025-12 | B13: 2025 | C13: 12 | D13: =DATE(B13,C13,1) -> 45992 | E13: =DAY(EOMONTH(D13,0)) -> 31

Sheet 月營運明細
A1: 年月 | B1: 年 | C1: 月 | D1: 門市代號 | E1: 門市名稱 | F1: 區域 | G1: 營業額 | H1: 食材成本 | I1: 人事成本 | J1: 租金 | K1: 水電及雜支 | L1: 行銷費用 | M1: 總成本 | N1: 營業利益 | O1: 營業利益率 | P1: 來客數 | Q1: 日均來客數 | R1: 平均客單價 | S1: 當月人氣餐點 | T1: 人氣餐點份數
A2: =TEXT(B2,"0")&"-"&TEXT(C2,"00") -> 2025-01 | B2: 2025 | C2: 1 | D2: TP01 | E2: =INDEX(門市主檔!$B$2:$B$9,MATCH($D2,門市主檔!$A$2:$A$9,0)) -> 台北信義旗艦店 | F2: =INDEX(門市主檔!$C$2:$C$9,MATCH($D2,門市主檔!$A$2:$A$9,0)) -> 北區 | G2: 3542000 | H2: 1067800 | I2: 852400 | J2: =INDEX(門市主檔!$G$2:$G$9,MATCH($D2,門市主檔!$A$2:$A$9,0)) -> 480000 | K2: 173200 | L2: 99300 | M2: =SUM(H2:L2) -> 2672700 | N2: =G2-M2 -> 869300 | O2: =IF(G2=0,0,N2/G2) -> 0.24542631 | P2: 9280 | Q2: =IF(P2=0,0,P2/INDEX(月曆參數!$E$2:$E$13,MATCH($A2,月曆參數!$A$2:$A$13,0))) -> 299.35484 | R2: =IF(P2=0,0,G2/P2) -> 381.68103 | S2: 酸菜白肉鍋 | T2: 780
A3: =TEXT(B3,"0")&"-"&TEXT(C3,"00") -> 2025-02 | B3: 2025 | C3: 2 | D3: TP01 | E3: =INDEX(門市主檔!$B$2:$B$9,MATCH($D3,門市主檔!$A$2:$A$9,0)) -> 台北信義旗艦店 | F3: =INDEX(門市主檔!$C$2:$C$9,MATCH($D3,門市主檔!$A$2:$A$9,0)) -> 北區 | G3: 2968000 | H3: 932900 | I3: 735300 | J3: =INDEX(門市主檔!$G$2:$G$9,MATCH($D3,門市主檔!$A$2:$A$9,0)) -> 480000 | K3: 146600 | L3: 94400 | M3: =SUM(H3:L3) -> 2389200 | N3: =G3-M3 -> 578800 | O3: =IF(G3=0,0,N3/G3) -> 0.19501348 | P3: 7930 | Q3: =IF(P3=0,0,P3/INDEX(月曆參數!$E$2:$E$13,MATCH($A3,月曆參數!$A$2:$A$13,0))) -> 283.21429 | R3: =IF(P3=0,0,G3/P3) -> 374.27491 | S3: 麻油雞湯麵 | T3: 610
A4: =TEXT(B4,"0")&"-"&TEXT(C4,"00") -> 2025-03 | B4: 2025 | C4: 3 | D4: TP01 | E4: =INDEX(門市主檔!$B$2:$B$9,MATCH($D4,門市主檔!$A$2:$A$9,0)) -> 台北信義旗艦店 | F4: =INDEX(門市主檔!$C$2:$C$9,MATCH($D4,門市主檔!$A$2:$A$9,0)) -> 北區 | G4: 2864000 | H4: 881900 | I4: 755100 | J4: =INDEX(門市主檔!$G$2:$G$9,MATCH($D4,門市主檔!$A$2:$A$9,0)) -> 480000 | K4: 184300 | L4: 91600 | M4: =SUM(H4:L4) -> 2392900 | N4: =G4-M4 -> 471100 | O4: =IF(G4=0,0,N4/G4) -> 0.16449022 | P4: 7430 | Q4: =IF(P4=0,0,P4/INDEX(月曆參數!$E$2:$E$13,MATCH($A4,月曆參數!$A$2:$A$13,0))) -> 239.67742 | R4: =IF(P4=0,0,G4/P4) -> 385.46433 | S4: 宮保雞丁飯 | T4: 680
A5: =TEXT(B5,"0")&"-"&TEXT(C5,"00") -> 2025-04 | B5: 2025 | C5: 4 | D5: TP01 | E5: =INDEX(門市主檔!$B$2:$B$9,MATCH($D5,門市主檔!$A$2:$A$9,0)) -> 台北信義旗艦店 | F5: =INDEX(門市主檔!$C$2:$C$9,MATCH($D5,門市主檔!$A$2:$A$9,0)) -> 北區 | G5: 2846000 | H5: 857800 | I5: 764800 | J5: =INDEX(門市主檔!$G$2:$G$9,MATCH($D5,門市主檔!$A$2:$A$9,0)) -> 480000 | K5: 161300 | L5: 61800 | M5: =SUM(H5:L5) -> 2325700 | N5: =G5-M5 -> 520300 | O5: =IF(G5=0,0,N5/G5) -> 0.18281799 | P5: 7040 | Q5: =IF(P5=0,0,P5/INDEX(月曆參數!$E$2:$E$13,MATCH($A5,月曆參數!$A$2:$A$13,0))) -> 234.66667 | R5: =IF(P5=0,0,G5/P5) -> 404.26136 | S5: 黑胡椒豬排飯 | T5: 600
A6: =TEXT(B6,"0")&"-"&TEXT(C6,"00") -> 2025-05 | B6: 2025 | C6: 5 | D6: TP01 | E6: =INDEX(門市主檔!$B$2:$B$9,MATCH($D6,門市主檔!$A$2:$A$9,0)) -> 台北信義旗艦店 | F6: =INDEX(門市主檔!$C$2:$C$9,MATCH($D6,門市主檔!$A$2:$A$9,0)) -> 北區 | G6: 2948000 | H6: 942600 | I6: 719900 | J6: =INDEX(門市主檔!$G$2:$G$9,MATCH($D6,門市主檔!$A$2:$A$9,0)) -> 480000 | K6: 184900 | L6: 82400 | M6: =SUM(H6:L6) -> 2409800 | N6: =G6-M6 -> 538200 | O6: =IF(G6=0,0,N6/G6) -> 0.18256445 | P6: 7480 | Q6: =IF(P6=0,0,P6/INDEX(月曆參數!$E$2:$E$13,MATCH($A6,月曆參數!$A$2:$A$13,0))) -> 241.29032 | R6: =IF(P6=0,0,G6/P6) -> 394.11765 | S6: 宮保雞丁飯 | T6: 510
A7: =TEXT(B7,"0")&"-"&TEXT(C7,"00") -> 2025-06 | B7: 2025 | C7: 6 | D7: TP01 | E7: =INDEX(門市主檔!$B$2:$B$9,MATCH($D7,門市主檔!$A$2:$A$9,0)) -> 台北信義旗艦店 | F7: =INDEX(門市主檔!$C$2:$C$9,MATCH($D7,門市主檔!$A$2:$A$9,0)) -> 北區 | G7: 2944000 | H7: 888600 | I7: 785100 | J7: =INDEX(門市主檔!$G$2:$G$9,MATCH($D7,門市主檔!$A$2:$A$9,0)) -> 480000 | K7: 152700 | L7: 54700 | M7: =SUM(H7:L7) -> 2361100 | N7: =G7-M7 -> 582900 | O7: =IF(G7=0,0,N7/G7) -> 0.19799592 | P7: 7280 | Q7: =IF(P7=0,0,P7/INDEX(月曆參數!$E$2:$E$13,MATCH($A7,月曆參數!$A$2:$A$13,0))) -> 242.66667 | R7: =IF(P7=0,0,G7/P7) -> 404.3956 | S7: 塔香涼麵套餐 | T7: 640
A8: =TEXT(B8,"0")&"-"&TEXT(C8,"00") -> 2025-07 | B8: 2025 | C8: 7 | D8: TP01 | E8: =INDEX(門市主檔!$B$2:$B$9,MATCH($D8,門市主檔!$A$2:$A$9,0)) -> 台北信義旗艦店 | F8: =INDEX(門市主檔!$C$2:$C$9,MATCH($D8,門市主檔!$A$2:$A$9,0)) -> 北區 | G8: 3335000 | H8: 1082600 | I8: 826200 | J8: =INDEX(門市主檔!$G$2:$G$9,MATCH($D8,門市主檔!$A$2:$A$9,0)) -> 480000 | K8: 172600 | L8: 66300 | M8: =SUM(H8:L8) -> 2627700 | N8: =G8-M8 -> 707300 | O8: =IF(G8=0,0,N8/G8) -> 0.21208396 | P8: 8930 | Q8: =IF(P8=0,0,P8/INDEX(月曆參數!$E$2:$E$13,MATCH($A8,月曆參數!$A$2:$A$13,0))) -> 288.06452 | R8: =IF(P8=0,0,G8/P8) -> 373.46025 | S8: 海鮮炒飯 | T8: 490
A9: =TEXT(B9,"0")&"-"&TEXT(C9,"00") -> 2025-08 | B9: 2025 | C9: 8 | D9: TP01 | E9: =INDEX(門市主檔!$B$2:$B$9,MATCH($D9,門市主檔!$A$2:$A$9,0)) -> 台北信義旗艦店 | F9: =INDEX(門市主檔!$C$2:$C$9,MATCH($D9,門市主檔!$A$2:$A$9,0)) -> 北區 | G9: 3190000 | H9: 1053800 | I9: 817500 | J9: =INDEX(門市主檔!$G$2:$G$9,MATCH($D9,門市主檔!$A$2:$A$9,0)) -> 480000 | K9: 163200 | L9: 74700 | M9: =SUM(H9:L9) -> 2589200 | N9: =G9-M9 -> 600800 | O9: =IF(G9=0,0,N9/G9) -> 0.18833856 | P9: 8540 | Q9: =IF(P9=0,0,P9/INDEX(月曆參數!$E$2:$E$13,MATCH($A9,月曆參數!$A$2:$A$13,0))) -> 275.48387 | R9: =IF(P9=0,0,G9/P9) -> 373.5363 | S9: 塔香涼麵套餐 | T9: 590
A10: =TEXT(B10,"0")&"-"&TEXT(C10,"00") -> 2025-09 | B10: 2025 | C10: 9 | D10: TP01 | E10: =INDEX(門市主檔!$B$2:$B$9,MATCH($D10,門市主檔!$A$2:$A$9,0)) -> 台北信義旗艦店 | F10: =INDEX(門市主檔!$C$2:$C$9,MATCH($D10,門市主檔!$A$2:$A$9,0)) -> 北區 | G10: 2807000 | H10: 885200 | I10: 693300 | J10: =INDEX(門市主檔!$G$2:$G$9,MATCH($D10,門市主檔!$A$2:$A$9,0)) -> 480000 | K10: 149700 | L10: 56500 | M10: =SUM(H10:L10) -> 2264700 | N10: =G10-M10 -> 542300 | O10: =IF(G10=0,0,N10/G10) -> 0.19319558 | P10: 7660 | Q10: =IF(P10=0,0,P10/INDEX(月曆參數!$E$2:$E$13,MATCH($A10,月曆參數!$A$2:$A$13,0))) -> 255.33333 | R10: =IF(P10=0,0,G10/P10) -> 366.44909 | S10: 三杯雞定食 | T10: 490
A11: =TEXT(B11,"0")&"-"&TEXT(C11,"00") -> 2025-10 | B11: 2025 | C11: 10 | D11: TP01 | E11: =INDEX(門市主檔!$B$2:$B$9,MATCH($D11,門市主檔!$A$2:$A$9,0)) -> 台北信義旗艦店 | F11: =INDEX(門市主檔!$C$2:$C$9,MATCH($D11,門市主檔!$A$2:$A$9,0)) -> 北區 | G11: 3222000 | H11: 1071200 | I11: 873700 | J11: =INDEX(門市主檔!$G$2:$G$9,MATCH($D11,門市主檔!$A$2:$A$9,0)) -> 480000 | K11: 197300 | L11: 96000 | M11: =SUM(H11:L11) -> 2718200 | N11: =G11-M11 -> 503800 | O11: =IF(G11=0,0,N11/G11) -> 0.15636251 | P11: 8650 | Q11: =IF(P11=0,0,P11/INDEX(月曆參數!$E$2:$E$13,MATCH($A11,月曆參數!$A$2:$A$13,0))) -> 279.03226 | R11: =IF(P11=0,0,G11/P11) -> 372.48555 | S11: 招牌牛肉麵 | T11: 720
A12: =TEXT(B12,"0")&"-"&TEXT(C12,"00") -> 2025-11 | B12: 2025 | C12: 11 | D12: TP01 | E12: =INDEX(門市主檔!$B$2:$B$9,MATCH($D12,門市主檔!$A$2:$A$9,0)) -> 台北信義旗艦店 | F12: =INDEX(門市主檔!$C$2:$C$9,MATCH($D12,門市主檔!$A$2:$A$9,0)) -> 北區 | G12: 2982000 | H12: 948700 | I12: 793300 | J12: =INDEX(門市主檔!$G$2:$G$9,MATCH($D12,門市主檔!$A$2:$A$9,0)) -> 480000 | K12: 175300 | L12: 80200 | M12: =SUM(H12:L12) -> 2477500 | N12: =G12-M12 -> 504500 | O12: =IF(G12=0,0,N12/G12) -> 0.16918176 | P12: 7440 | Q12: =IF(P12=0,0,P12/INDEX(月曆參數!$E$2:$E$13,MATCH($A12,月曆參數!$A$2:$A$13,0))) -> 248 | R12: =IF(P12=0,0,G12/P12) -> 400.80645 | S12: 三杯雞定食 | T12: 610
A13: =TEXT(B13,"0")&"-"&TEXT(C13,"00") -> 2025-12 | B13: 2025 | C13: 12 | D13: TP01 | E13: =INDEX(門市主檔!$B$2:$B$9,MATCH($D13,門市主檔!$A$2:$A$9,0)) -> 台北信義旗艦店 | F13: =INDEX(門市主檔!$C$2:$C$9,MATCH($D13,門市主檔!$A$2:$A$9,0)) -> 北區 | G13: 3291000 | H13: 1077800 | I13: 828400 | J13: =INDEX(門市主檔!$G$2:$G$9,MATCH($D13,門市主檔!$A$2:$A$9,0)) -> 480000 | K13: 166600 | L13: 84900 | M13: =SUM(H13:L13) -> 2637700 | N13: =G13-M13 -> 653300 | O13: =IF(G13=0,0,N13/G13) -> 0.19851109 | P13: 8710 | Q13: =IF(P13=0,0,P13/INDEX(月曆參數!$E$2:$E$13,MATCH($A13,月曆參數!$A$2:$A$13,0))) -> 280.96774 | R13: =IF(P13=0,0,G13/P13) -> 377.84156 | S13: 紅燒牛肉麵 | T13: 800
... A97: =TEXT(B97,"0")&"-"&TEXT(C97,"00") -> 2025-12 | B97: 2025 | C97: 12 | D97: KH01 | E97: =INDEX(門市主檔!$B$2:$B$9,MATCH($D97,門市主檔!$A$2:$A$9,0)) -> 高雄左營店 | F97: =INDEX(門市主檔!$C$2:$C$9,MATCH($D97,門市主檔!$A$2:$A$9,0)) -> 南區 | G97: 2617000 | H97: 790200 | I97: 625500 | J97: =INDEX(門市主檔!$G$2:$G$9,MATCH($D97,門市主檔!$A$2:$A$9,0)) -> 210000 | K97: 154600 | L97: 79100 | M97: =SUM(H97:L97) -> 1859400 | N97: =G97-M97 -> 757600 | O97: =IF(G97=0,0,N97/G97) -> 0.28949178 | P97: 8570 | Q97: =IF(P97=0,0,P97/INDEX(月曆參數!$E$2:$E$13,MATCH($A97,月曆參數!$A$2:$A$13,0))) -> 276.45161 | R97: =IF(P97=0,0,G97/P97) -> 305.36756 | S97: 紅燒牛肉麵 | T97: 630

Sheet 門市年度彙總
A1: 門市代號 | B1: 門市名稱 | C1: 區域 | D1: 年營業額 | E1: 年總成本 | F1: 年營業利益 | G1: 營業利益率 | H1: 年來客數 | I1: 日均來客數 | J1: 平均客單價 | K1: 最佳月份 | L1: 最佳月營業額 | M1: 營業額排名
A2: TP01 | B2: =INDEX(門市主檔!$B$2:$B$9,MATCH($A2,門市主檔!$A$2:$A$9,0)) -> 台北信義旗艦店 | C2: =INDEX(門市主檔!$C$2:$C$9,MATCH($A2,門市主檔!$A$2:$A$9,0)) -> 北區 | D2: =SUMIFS(月營運明細!$G$2:$G$97,月營運明細!$D$2:$D$97,$A2) -> 36939000 | E2: =SUMIFS(月營運明細!$M$2:$M$97,月營運明細!$D$2:$D$97,$A2) -> 29866400 | F2: =D2-E2 -> 7072600 | G2: =IF(D2=0,0,F2/D2) -> 0.19146701 | H2: =SUMIFS(月營運明細!$P$2:$P$97,月營運明細!$D$2:$D$97,$A2) -> 96370 | I2: =IF(SUM(月曆參數!$E$2:$E$13)=0,0,H2/SUM(月曆參數!$E$2:$E$13)) -> 264.0274 | J2: =IF(H2=0,0,D2/H2) -> 383.30393 | K2: =SUMPRODUCT((月營運明細!$D$2:$D$97=$A2)*(月營運明細!$G$2:$G$97=$L2)*月營運明細!$C$2:$C$97) -> 1 | L2: =SUMPRODUCT(MAX((月營運明細!$D$2:$D$97=$A2)*月營運明細!$G$2:$G$97)) -> 3542000 | M2: =RANK(D2,$D$2:$D$9) -> 1
A3: TP02 | B3: =INDEX(門市主檔!$B$2:$B$9,MATCH($A3,門市主檔!$A$2:$A$9,0)) -> 台北中山店 | C3: =INDEX(門市主檔!$C$2:$C$9,MATCH($A3,門市主檔!$A$2:$A$9,0)) -> 北區 | D3: =SUMIFS(月營運明細!$G$2:$G$97,月營運明細!$D$2:$D$97,$A3) -> 28101000 | E3: =SUMIFS(月營運明細!$M$2:$M$97,月營運明細!$D$2:$D$97,$A3) -> 22542000 | F3: =D3-E3 -> 5559000 | G3: =IF(D3=0,0,F3/D3) -> 0.19782214 | H3: =SUMIFS(月營運明細!$P$2:$P$97,月營運明細!$D$2:$D$97,$A3) -> 79150 | I3: =IF(SUM(月曆參數!$E$2:$E$13)=0,0,H3/SUM(月曆參數!$E$2:$E$13)) -> 216.84932 | J3: =IF(H3=0,0,D3/H3) -> 355.03474 | K3: =SUMPRODUCT((月營運明細!$D$2:$D$97=$A3)*(月營運明細!$G$2:$G$97=$L3)*月營運明細!$C$2:$C$97) -> 12 | L3: =SUMPRODUCT(MAX((月營運明細!$D$2:$D$97=$A3)*月營運明細!$G$2:$G$97)) -> 2710000 | M3: =RANK(D3,$D$2:$D$9) -> 4
A4: NT01 | B4: =INDEX(門市主檔!$B$2:$B$9,MATCH($A4,門市主檔!$A$2:$A$9,0)) -> 新北板橋店 | C4: =INDEX(門市主檔!$C$2:$C$9,MATCH($A4,門市主檔!$A$2:$A$9,0)) -> 北區 | D4: =SUMIFS(月營運明細!$G$2:$G$97,月營運明細!$D$2:$D$97,$A4) -> 29272000 | E4: =SUMIFS(月營運明細!$M$2:$M$97,月營運明細!$D$2:$D$97,$A4) -> 22561900 | F4: =D4-E4 -> 6710100 | G4: =IF(D4=0,0,F4/D4) -> 0.22923271 | H4: =SUMIFS(月營運明細!$P$2:$P$97,月營運明細!$D$2:$D$97,$A4) -> 95450 | I4: =IF(SUM(月曆參數!$E$2:$E$13)=0,0,H4/SUM(月曆參數!$E$2:$E$13)) -> 261.50685 | J4: =IF(H4=0,0,D4/H4) -> 306.67365 | K4: =SUMPRODUCT((月營運明細!$D$2:$D$97=$A4)*(月營運明細!$G$2:$G$97=$L4)*月營運明細!$C$2:$C$97) -> 8 | L4: =SUMPRODUCT(MAX((月營運明細!$D$2:$D$97=$A4)*月營運明細!$G$2:$G$97)) -> 2761000 | M4: =RANK(D4,$D$2:$D$9) -> 3
A5: TY01 | B5: =INDEX(門市主檔!$B$2:$B$9,MATCH($A5,門市主檔!$A$2:$A$9,0)) -> 桃園中壢店 | C5: =INDEX(門市主檔!$C$2:$C$9,MATCH($A5,門市主檔!$A$2:$A$9,0)) -> 北區 | D5: =SUMIFS(月營運明細!$G$2:$G$97,月營運明細!$D$2:$D$97,$A5) -> 23153000 | E5: =SUMIFS(月營運明細!$M$2:$M$97,月營運明細!$D$2:$D$97,$A5) -> 17498000 | F5: =D5-E5 -> 5655000 | G5: =IF(D5=0,0,F5/D5) -> 0.24424481 | H5: =SUMIFS(月營運明細!$P$2:$P$97,月營運明細!$D$2:$D$97,$A5) -> 81300 | I5: =IF(SUM(月曆參數!$E$2:$E$13)=0,0,H5/SUM(月曆參數!$E$2:$E$13)) -> 222.73973 | J5: =IF(H5=0,0,D5/H5) -> 284.78475 | K5: =SUMPRODUCT((月營運明細!$D$2:$D$97=$A5)*(月營運明細!$G$2:$G$97=$L5)*月營運明細!$C$2:$C$97) -> 12 | L5: =SUMPRODUCT(MAX((月營運明細!$D$2:$D$97=$A5)*月營運明細!$G$2:$G$97)) -> 2180000 | M5: =RANK(D5,$D$2:$D$9) -> 7
A6: TC01 | B6: =INDEX(門市主檔!$B$2:$B$9,MATCH($A6,門市主檔!$A$2:$A$9,0)) -> 台中逢甲店 | C6: =INDEX(門市主檔!$C$2:$C$9,MATCH($A6,門市主檔!$A$2:$A$9,0)) -> 中區 | D6: =SUMIFS(月營運明細!$G$2:$G$97,月營運明細!$D$2:$D$97,$A6) -> 30550000 | E6: =SUMIFS(月營運明細!$M$2:$M$97,月營運明細!$D$2:$D$97,$A6) -> 22865300 | F6: =D6-E6 -> 7684700 | G6: =IF(D6=0,0,F6/D6) -> 0.25154501 | H6: =SUMIFS(月營運明細!$P$2:$P$97,月營運明細!$D$2:$D$97,$A6) -> 109380 | I6: =IF(SUM(月曆參數!$E$2:$E$13)=0,0,H6/SUM(月曆參數!$E$2:$E$13)) -> 299.67123 | J6: =IF(H6=0,0,D6/H6) -> 279.30152 | K6: =SUMPRODUCT((月營運明細!$D$2:$D$97=$A6)*(月營運明細!$G$2:$G$97=$L6)*月營運明細!$C$2:$C$97) -> 8 | L6: =SUMPRODUCT(MAX((月營運明細!$D$2:$D$97=$A6)*月營運明細!$G$2:$G$97)) -> 2880000 | M6: =RANK(D6,$D$2:$D$9) -> 2
A7: TC02 | B7: =INDEX(門市主檔!$B$2:$B$9,MATCH($A7,門市主檔!$A$2:$A$9,0)) -> 台中七期店 | C7: =INDEX(門市主檔!$C$2:$C$9,MATCH($A7,門市主檔!$A$2:$A$9,0)) -> 中區 | D7: =SUMIFS(月營運明細!$G$2:$G$97,月營運明細!$D$2:$D$97,$A7) -> 26174000 | E7: =SUMIFS(月營運明細!$M$2:$M$97,月營運明細!$D$2:$D$97,$A7) -> 20714400 | F7: =D7-E7 -> 5459600 | G7: =IF(D7=0,0,F7/D7) -> 0.20858868 | H7: =SUMIFS(月營運明細!$P$2:$P$97,月營運明細!$D$2:$D$97,$A7) -> 74610 | I7: =IF(SUM(月曆參數!$E$2:$E$13)=0,0,H7/SUM(月曆參數!$E$2:$E$13)) -> 204.41096 | J7: =IF(H7=0,0,D7/H7) -> 350.81088 | K7: =SUMPRODUCT((月營運明細!$D$2:$D$97=$A7)*(月營運明細!$G$2:$G$97=$L7)*月營運明細!$C$2:$C$97) -> 1 | L7: =SUMPRODUCT(MAX((月營運明細!$D$2:$D$97=$A7)*月營運明細!$G$2:$G$97)) -> 2462000 | M7: =RANK(D7,$D$2:$D$9) -> 6
A8: TN01 | B8: =INDEX(門市主檔!$B$2:$B$9,MATCH($A8,門市主檔!$A$2:$A$9,0)) -> 台南中西店 | C8: =INDEX(門市主檔!$C$2:$C$9,MATCH($A8,門市主檔!$A$2:$A$9,0)) -> 南區 | D8: =SUMIFS(月營運明細!$G$2:$G$97,月營運明細!$D$2:$D$97,$A8) -> 21591000 | E8: =SUMIFS(月營運明細!$M$2:$M$97,月營運明細!$D$2:$D$97,$A8) -> 16196100 | F8: =D8-E8 -> 5394900 | G8: =IF(D8=0,0,F8/D8) -> 0.249868 | H8: =SUMIFS(月營運明細!$P$2:$P$97,月營運明細!$D$2:$D$97,$A8) -> 80660 | I8: =IF(SUM(月曆參數!$E$2:$E$13)=0,0,H8/SUM(月曆參數!$E$2:$E$13)) -> 220.9863 | J8: =IF(H8=0,0,D8/H8) -> 267.67915 | K8: =SUMPRODUCT((月營運明細!$D$2:$D$97=$A8)*(月營運明細!$G$2:$G$97=$L8)*月營運明細!$C$2:$C$97) -> 8 | L8: =SUMPRODUCT(MAX((月營運明細!$D$2:$D$97=$A8)*月營運明細!$G$2:$G$97)) -> 1966000 | M8: =RANK(D8,$D$2:$D$9) -> 8
A9: KH01 | B9: =INDEX(門市主檔!$B$2:$B$9,MATCH($A9,門市主檔!$A$2:$A$9,0)) -> 高雄左營店 | C9: =INDEX(門市主檔!$C$2:$C$9,MATCH($A9,門市主檔!$A$2:$A$9,0)) -> 南區 | D9: =SUMIFS(月營運明細!$G$2:$G$97,月營運明細!$D$2:$D$97,$A9) -> 28033000 | E9: =SUMIFS(月營運明細!$M$2:$M$97,月營運明細!$D$2:$D$97,$A9) -> 20974700 | F9: =D9-E9 -> 7058300 | G9: =IF(D9=0,0,F9/D9) -> 0.2517854 | H9: =SUMIFS(月營運明細!$P$2:$P$97,月營運明細!$D$2:$D$97,$A9) -> 95580 | I9: =IF(SUM(月曆參數!$E$2:$E$13)=0,0,H9/SUM(月曆參數!$E$2:$E$13)) -> 261.86301 | J9: =IF(H9=0,0,D9/H9) -> 293.29358 | K9: =SUMPRODUCT((月營運明細!$D$2:$D$97=$A9)*(月營運明細!$G$2:$G$97=$L9)*月營運明細!$C$2:$C$97) -> 12 | L9: =SUMPRODUCT(MAX((月營運明細!$D$2:$D$97=$A9)*月營運明細!$G$2:$G$97)) -> 2617000 | M9: =RANK(D9,$D$2:$D$9) -> 5

Sheet 月度彙總
A1: 年月 | B1: 年 | C1: 月 | D1: 營業額 | E1: 總成本 | F1: 營業利益 | G1: 營業利益率 | H1: 來客數 | I1: 日均來客數 | J1: 平均客單價 | K1: 營業額月增率
A2: =月曆參數!A2 -> 2025-01 | B2: =月曆參數!B2 -> 2025 | C2: =月曆參數!C2 -> 1 | D2: =SUMIFS(月營運明細!$G$2:$G$97,月營運明細!$A$2:$A$97,$A2) -> 20351000 | E2: =SUMIFS(月營運明細!$M$2:$M$97,月營運明細!$A$2:$A$97,$A2) -> 15538700 | F2: =D2-E2 -> 4812300 | G2: =IF(D2=0,0,F2/D2) -> 0.23646504 | H2: =SUMIFS(月營運明細!$P$2:$P$97,月營運明細!$A$2:$A$97,$A2) -> 65300 | I2: =IF(月曆參數!E2=0,0,H2/月曆參數!E2) -> 2106.4516 | J2: =IF(H2=0,0,D2/H2) -> 311.65391
A3: =月曆參數!A3 -> 2025-02 | B3: =月曆參數!B3 -> 2025 | C3: =月曆參數!C3 -> 2 | D3: =SUMIFS(月營運明細!$G$2:$G$97,月營運明細!$A$2:$A$97,$A3) -> 18518000 | E3: =SUMIFS(月營運明細!$M$2:$M$97,月營運明細!$A$2:$A$97,$A3) -> 14345100 | F3: =D3-E3 -> 4172900 | G3: =IF(D3=0,0,F3/D3) -> 0.22534291 | H3: =SUMIFS(月營運明細!$P$2:$P$97,月營運明細!$A$2:$A$97,$A3) -> 58660 | I3: =IF(月曆參數!E3=0,0,H3/月曆參數!E3) -> 2095 | J3: =IF(H3=0,0,D3/H3) -> 315.6836 | K3: =IF(D2=0,0,D3/D2-1) -> -0.090069284
A4: =月曆參數!A4 -> 2025-03 | B4: =月曆參數!B4 -> 2025 | C4: =月曆參數!C4 -> 3 | D4: =SUMIFS(月營運明細!$G$2:$G$97,月營運明細!$A$2:$A$97,$A4) -> 16834000 | E4: =SUMIFS(月營運明細!$M$2:$M$97,月營運明細!$A$2:$A$97,$A4) -> 13366000 | F4: =D4-E4 -> 3468000 | G4: =IF(D4=0,0,F4/D4) -> 0.20601164 | H4: =SUMIFS(月營運明細!$P$2:$P$97,月營運明細!$A$2:$A$97,$A4) -> 54490 | I4: =IF(月曆參數!E4=0,0,H4/月曆參數!E4) -> 1757.7419 | J4: =IF(H4=0,0,D4/H4) -> 308.93742 | K4: =IF(D3=0,0,D4/D3-1) -> -0.090938546
A5: =月曆參數!A5 -> 2025-04 | B5: =月曆參數!B5 -> 2025 | C5: =月曆參數!C5 -> 4 | D5: =SUMIFS(月營運明細!$G$2:$G$97,月營運明細!$A$2:$A$97,$A5) -> 17264000 | E5: =SUMIFS(月營運明細!$M$2:$M$97,月營運明細!$A$2:$A$97,$A5) -> 13646200 | F5: =D5-E5 -> 3617800 | G5: =IF(D5=0,0,F5/D5) -> 0.20955746 | H5: =SUMIFS(月營運明細!$P$2:$P$97,月營運明細!$A$2:$A$97,$A5) -> 54940 | I5: =IF(月曆參數!E5=0,0,H5/月曆參數!E5) -> 1831.3333 | J5: =IF(H5=0,0,D5/H5) -> 314.23371 | K5: =IF(D4=0,0,D5/D4-1) -> 0.025543543
A6: =月曆參數!A6 -> 2025-05 | B6: =月曆參數!B6 -> 2025 | C6: =月曆參數!C6 -> 5 | D6: =SUMIFS(月營運明細!$G$2:$G$97,月營運明細!$A$2:$A$97,$A6) -> 17467000 | E6: =SUMIFS(月營運明細!$M$2:$M$97,月營運明細!$A$2:$A$97,$A6) -> 13564700 | F6: =D6-E6 -> 3902300 | G6: =IF(D6=0,0,F6/D6) -> 0.22340986 | H6: =SUMIFS(月營運明細!$P$2:$P$97,月營運明細!$A$2:$A$97,$A6) -> 55660 | I6: =IF(月曆參數!E6=0,0,H6/月曆參數!E6) -> 1795.4839 | J6: =IF(H6=0,0,D6/H6) -> 313.81603 | K6: =IF(D5=0,0,D6/D5-1) -> 0.011758573
A7: =月曆參數!A7 -> 2025-06 | B7: =月曆參數!B7 -> 2025 | C7: =月曆參數!C7 -> 6 | D7: =SUMIFS(月營運明細!$G$2:$G$97,月營運明細!$A$2:$A$97,$A7) -> 17576000 | E7: =SUMIFS(月營運明細!$M$2:$M$97,月營運明細!$A$2:$A$97,$A7) -> 13699100 | F7: =D7-E7 -> 3876900 | G7: =IF(D7=0,0,F7/D7) -> 0.2205792 | H7: =SUMIFS(月營運明細!$P$2:$P$97,月營運明細!$A$2:$A$97,$A7) -> 54710 | I7: =IF(月曆參數!E7=0,0,H7/月曆參數!E7) -> 1823.6667 | J7: =IF(H7=0,0,D7/H7) -> 321.25754 | K7: =IF(D6=0,0,D7/D6-1) -> 0.0062403389
A8: =月曆參數!A8 -> 2025-07 | B8: =月曆參數!B8 -> 2025 | C8: =月曆參數!C8 -> 7 | D8: =SUMIFS(月營運明細!$G$2:$G$97,月營運明細!$A$2:$A$97,$A8) -> 19512000 | E8: =SUMIFS(月營運明細!$M$2:$M$97,月營運明細!$A$2:$A$97,$A8) -> 15062700 | F8: =D8-E8 -> 4449300 | G8: =IF(D8=0,0,F8/D8) -> 0.22802891 | H8: =SUMIFS(月營運明細!$P$2:$P$97,月營運明細!$A$2:$A$97,$A8) -> 62030 | I8: =IF(月曆參數!E8=0,0,H8/月曆參數!E8) -> 2000.9677 | J8: =IF(H8=0,0,D8/H8) -> 314.55747 | K8: =IF(D7=0,0,D8/D7-1) -> 0.1101502
A9: =月曆參數!A9 -> 2025-08 | B9: =月曆參數!B9 -> 2025 | C9: =月曆參數!C9 -> 8 | D9: =SUMIFS(月營運明細!$G$2:$G$97,月營運明細!$A$2:$A$97,$A9) -> 20218000 | E9: =SUMIFS(月營運明細!$M$2:$M$97,月營運明細!$A$2:$A$97,$A9) -> 15484300 | F9: =D9-E9 -> 4733700 | G9: =IF(D9=0,0,F9/D9) -> 0.23413295 | H9: =SUMIFS(月營運明細!$P$2:$P$97,月營運明細!$A$2:$A$97,$A9) -> 63700 | I9: =IF(月曆參數!E9=0,0,H9/月曆參數!E9) -> 2054.8387 | J9: =IF(H9=0,0,D9/H9) -> 317.39403 | K9: =IF(D8=0,0,D9/D8-1) -> 0.036182862
A10: =月曆參數!A10 -> 2025-09 | B10: =月曆參數!B10 -> 2025 | C10: =月曆參數!C10 -> 9 | D10: =SUMIFS(月營運明細!$G$2:$G$97,月營運明細!$A$2:$A$97,$A10) -> 17977000 | E10: =SUMIFS(月營運明細!$M$2:$M$97,月營運明細!$A$2:$A$97,$A10) -> 13816900 | F10: =D10-E10 -> 4160100 | G10: =IF(D10=0,0,F10/D10) -> 0.23141236 | H10: =SUMIFS(月營運明細!$P$2:$P$97,月營運明細!$A$2:$A$97,$A10) -> 57350 | I10: =IF(月曆參數!E10=0,0,H10/月曆參數!E10) -> 1911.6667 | J10: =IF(H10=0,0,D10/H10) -> 313.4612 | K10: =IF(D9=0,0,D10/D9-1) -> -0.11084182
A11: =月曆參數!A11 -> 2025-10 | B11: =月曆參數!B11 -> 2025 | C11: =月曆參數!C11 -> 10 | D11: =SUMIFS(月營運明細!$G$2:$G$97,月營運明細!$A$2:$A$97,$A11) -> 18853000 | E11: =SUMIFS(月營運明細!$M$2:$M$97,月營運明細!$A$2:$A$97,$A11) -> 14629800 | F11: =D11-E11 -> 4223200 | G11: =IF(D11=0,0,F11/D11) -> 0.22400679 | H11: =SUMIFS(月營運明細!$P$2:$P$97,月營運明細!$A$2:$A$97,$A11) -> 60000 | I11: =IF(月曆參數!E11=0,0,H11/月曆參數!E11) -> 1935.4839 | J11: =IF(H11=0,0,D11/H11) -> 314.21667 | K11: =IF(D10=0,0,D11/D10-1) -> 0.048728931
A12: =月曆參數!A12 -> 2025-11 | B12: =月曆參數!B12 -> 2025 | C12: =月曆參數!C12 -> 11 | D12: =SUMIFS(月營運明細!$G$2:$G$97,月營運明細!$A$2:$A$97,$A12) -> 18526000 | E12: =SUMIFS(月營運明細!$M$2:$M$97,月營運明細!$A$2:$A$97,$A12) -> 14354500 | F12: =D12-E12 -> 4171500 | G12: =IF(D12=0,0,F12/D12) -> 0.22517003 | H12: =SUMIFS(月營運明細!$P$2:$P$97,月營運明細!$A$2:$A$97,$A12) -> 59190 | I12: =IF(月曆參數!E12=0,0,H12/月曆參數!E12) -> 1973 | J12: =IF(H12=0,0,D12/H12) -> 312.99206 | K12: =IF(D11=0,0,D12/D11-1) -> -0.01734472
A13: =月曆參數!A13 -> 2025-12 | B13: =月曆參數!B13 -> 2025 | C13: =月曆參數!C13 -> 12 | D13: =SUMIFS(月營運明細!$G$2:$G$97,月營運明細!$A$2:$A$97,$A13) -> 20717000 | E13: =SUMIFS(月營運明細!$M$2:$M$97,月營運明細!$A$2:$A$97,$A13) -> 15710800 | F13: =D13-E13 -> 5006200 | G13: =IF(D13=0,0,F13/D13) -> 0.24164696 | H13: =SUMIFS(月營運明細!$P$2:$P$97,月營運明細!$A$2:$A$97,$A13) -> 66470 | I13: =IF(月曆參數!E13=0,0,H13/月曆參數!E13) -> 2144.1935 | J13: =IF(H13=0,0,D13/H13) -> 311.67444 | K13: =IF(D12=0,0,D13/D12-1) -> 0.11826622

Sheet 人氣餐點彙總
A1: 餐點名稱 | B1: 上榜次數 | C1: 總份數 | D1: 份數佔比
A2: 三杯雞定食 | B2: =COUNTIF(月營運明細!$S$2:$S$97,$A2) -> 11 | C2: =SUMIF(月營運明細!$S$2:$S$97,$A2,月營運明細!$T$2:$T$97) -> 6030 | D2: =IF(SUM($C$2:$C$14)=0,0,C2/SUM($C$2:$C$14)) -> 0.11247902
A3: 塔香涼麵套餐 | B3: =COUNTIF(月營運明細!$S$2:$S$97,$A3) -> 5 | C3: =SUMIF(月營運明細!$S$2:$S$97,$A3,月營運明細!$T$2:$T$97) -> 2890 | D3: =IF(SUM($C$2:$C$14)=0,0,C3/SUM($C$2:$C$14)) -> 0.053907853
A4: 宮保雞丁飯 | B4: =COUNTIF(月營運明細!$S$2:$S$97,$A4) -> 10 | C4: =SUMIF(月營運明細!$S$2:$S$97,$A4,月營運明細!$T$2:$T$97) -> 5230 | D4: =IF(SUM($C$2:$C$14)=0,0,C4/SUM($C$2:$C$14)) -> 0.097556426
A5: 招牌牛肉麵 | B5: =COUNTIF(月營運明細!$S$2:$S$97,$A5) -> 11 | C5: =SUMIF(月營運明細!$S$2:$S$97,$A5,月營運明細!$T$2:$T$97) -> 6220 | D5: =IF(SUM($C$2:$C$14)=0,0,C5/SUM($C$2:$C$14)) -> 0.11602313
A6: 檸檬蒸魚定食 | B6: =COUNTIF(月營運明細!$S$2:$S$97,$A6) -> 6 | C6: =SUMIF(月營運明細!$S$2:$S$97,$A6,月營運明細!$T$2:$T$97) -> 3680 | D6: =IF(SUM($C$2:$C$14)=0,0,C6/SUM($C$2:$C$14)) -> 0.06864391
A7: 泰式打拋豬飯 | B7: =COUNTIF(月營運明細!$S$2:$S$97,$A7) -> 4 | C7: =SUMIF(月營運明細!$S$2:$S$97,$A7,月營運明細!$T$2:$T$97) -> 2450 | D7: =IF(SUM($C$2:$C$14)=0,0,C7/SUM($C$2:$C$14)) -> 0.045700429
A8: 海鮮炒飯 | B8: =COUNTIF(月營運明細!$S$2:$S$97,$A8) -> 9 | C8: =SUMIF(月營運明細!$S$2:$S$97,$A8,月營運明細!$T$2:$T$97) -> 5190 | D8: =IF(SUM($C$2:$C$14)=0,0,C8/SUM($C$2:$C$14)) -> 0.096810297
A9: 紅燒牛肉麵 | B9: =COUNTIF(月營運明細!$S$2:$S$97,$A9) -> 7 | C9: =SUMIF(月營運明細!$S$2:$S$97,$A9,月營運明細!$T$2:$T$97) -> 4560 | D9: =IF(SUM($C$2:$C$14)=0,0,C9/SUM($C$2:$C$14)) -> 0.085058758
A10: 蔥油雞腿飯 | B10: =COUNTIF(月營運明細!$S$2:$S$97,$A10) -> 3 | C10: =SUMIF(月營運明細!$S$2:$S$97,$A10,月營運明細!$T$2:$T$97) -> 1620 | D10: =IF(SUM($C$2:$C$14)=0,0,C10/SUM($C$2:$C$14)) -> 0.030218243
A11: 藥燉排骨鍋 | B11: =COUNTIF(月營運明細!$S$2:$S$97,$A11) -> 6 | C11: =SUMIF(月營運明細!$S$2:$S$97,$A11,月營運明細!$T$2:$T$97) -> 3230 | D11: =IF(SUM($C$2:$C$14)=0,0,C11/SUM($C$2:$C$14)) -> 0.060249953
A12: 酸菜白肉鍋 | B12: =COUNTIF(月營運明細!$S$2:$S$97,$A12) -> 6 | C12: =SUMIF(月營運明細!$S$2:$S$97,$A12,月營運明細!$T$2:$T$97) -> 3510 | D12: =IF(SUM($C$2:$C$14)=0,0,C12/SUM($C$2:$C$14)) -> 0.06547286
A13: 麻油雞湯麵 | B13: =COUNTIF(月營運明細!$S$2:$S$97,$A13) -> 5 | C13: =SUMIF(月營運明細!$S$2:$S$97,$A13,月營運明細!$T$2:$T$97) -> 3070 | D13: =IF(SUM($C$2:$C$14)=0,0,C13/SUM($C$2:$C$14)) -> 0.057265436
A14: 黑胡椒豬排飯 | B14: =COUNTIF(月營運明細!$S$2:$S$97,$A14) -> 13 | C14: =SUMIF(月營運明細!$S$2:$S$97,$A14,月營運明細!$T$2:$T$97) -> 5930 | D14: =IF(SUM($C$2:$C$14)=0,0,C14/SUM($C$2:$C$14)) -> 0.11061369

Sheet 年度關鍵指標
A1: 指標代碼 | B1: 指標名稱 | C1: 數值 | D1: 單位
A2: total_revenue | B2: 全年營業額 | C2: =SUM(月營運明細!$G$2:$G$97) -> 223813000 | D2: NT$
A3: total_cost | B3: 全年總成本 | C3: =SUM(月營運明細!$M$2:$M$97) -> 173218800 | D3: NT$
A4: total_profit | B4: 全年營業利益 | C4: =SUM(月營運明細!$N$2:$N$97) -> 50594200 | D4: NT$
A5: op_margin | B5: 營業利益率 | C5: =IF(C2=0,0,C4/C2) -> 0.22605568 | D5: 小數
A6: total_guests | B6: 全年來客數 | C6: =SUM(月營運明細!$P$2:$P$97) -> 712500 | D6: 人次
A7: guests_daily | B7: 全公司日均來客數 | C7: =IF(SUM(月曆參數!$E$2:$E$13)=0,0,C6/SUM(月曆參數!$E$2:$E$13)) -> 1952.0548 | D7: 人次/日
A8: avg_ticket | B8: 平均客單價 | C8: =IF(C6=0,0,C2/C6) -> 314.12351 | D8: NT$
A9: store_count | B9: 門市家數 | C9: =COUNTA(門市主檔!$A$2:$A$9) -> 8 | D9: 家
A10: rev_per_store | B10: 單店平均年營業額 | C10: =IF(C9=0,0,C2/C9) -> 27976625 | D10: NT$
A11: ratio_food | B11: 食材成本率 | C11: =IF(C2=0,0,SUM(月營運明細!$H$2:$H$97)/C2) -> 0.31925223 | D11: 小數
A12: ratio_labor | B12: 人事成本率 | C12: =IF(C2=0,0,SUM(月營運明細!$I$2:$I$97)/C2) -> 0.25656284 | D12: 小數
A13: ratio_rent | B13: 租金成本率 | C13: =IF(C2=0,0,SUM(月營運明細!$J$2:$J$97)/C2) -> 0.11473864 | D13: 小數
A14: ratio_utility | B14: 水電雜支率 | C14: =IF(C2=0,0,SUM(月營運明細!$K$2:$K$97)/C2) -> 0.057846059 | D14: 小數
A15: ratio_mkt | B15: 行銷費用率 | C15: =IF(C2=0,0,SUM(月營運明細!$L$2:$L$97)/C2) -> 0.025544539 | D15: 小數

Sheet 圖表預覽
A1: 此工作表僅供人工檢視，不含原始資料；自動化流程請略過。
